Workbook
Name Despesas_Administrativas: #REF!
Name Despesas_Com_RH: #REF!
Name Despesas_Comerciais: #REF!
Name Despesas_Endividamentos: #REF!
Name Despesas_Impostos: #REF!
Name Despesas_Investimentos: #REF!
Name Despesas_N_Operacionais: #REF!
Name Despesas_Operacionais: #REF!
Name LISTA_CLIENTES: OFFSET(#REF!,0,0,COUNTA(#REF!),1)
Name LISTA_FORNECEDORES: OFFSET(#REF!,0,0,COUNTA(#REF!),1)
Name Plano_de_contas: #REF!
Name Receitas_N_Operacionais: #REF!
Name Receitas_Operacionais: #REF!

Sheet FC
A1: FLUXO DE CAIXA MENSAL
A2: - | B2: JANEIRO | C2: FEVEREIRO | D2: MARÇO | E2: ABRIL | F2: MAIO | G2: JUNHO | H2: JULHO | I2: AGOSTO | J2: SETEMBRO | K2: OUTUBRO | L2: NOVEMBRO | M2: DEZEMBRO | N2: TOTAL
A3: ( + ) Disponíveis | B3: =B4+B13+B20 -> 0 | C3: =C4+C13+C20 -> 0 | D3: =D4+D13+D20 -> 0 | E3: =E4+E13+E20 -> 0 | F3: =F4+F13+F20 -> 0 | G3: =G4+G13+G20 -> 0 | H3: =H4+H13+H20 -> 0 | I3: =I4+I13+I20 -> 0 | ... N3: =N4+N13+N20 -> 0
A4: Bancos | B4: =SUM(B5:B12) -> 0 | C4: =SUM(C5:C12) -> 0 | D4: =SUM(D5:D12) -> 0 | E4: =SUM(E5:E12) -> 0 | F4: =SUM(F5:F12) -> 0 | G4: =SUM(G5:G12) -> 0 | H4: =SUM(H5:H12) -> 0 | I4: =SUM(I5:I12) -> 0 | ... N4: =SUM(N5:N12) -> 0
A5: Banco 1 (ag / cc ) | N5: =SUM(FCJAN[[#This Row],[JANEIRO]:[DEZEMBRO]]) -> 0
A6: Banco 2 (ag / cc ) | N6: =SUM(FCJAN[[#This Row],[JANEIRO]:[DEZEMBRO]]) -> 0
A7: Banco 3 (ag / cc ) | N7: =SUM(FCJAN[[#This Row],[JANEIRO]:[DEZEMBRO]]) -> 0
N8: =SUM(FCJAN[[#This Row],[JANEIRO]:[DEZEMBRO]]) -> 0
N9: =SUM(FCJAN[[#This Row],[JANEIRO]:[DEZEMBRO]]) -> 0
N10: =SUM(FCJAN[[#This Row],[JANEIRO]:[DEZEMBRO]]) -> 0
N11: =SUM(FCJAN[[#This Row],[JANEIRO]:[DEZEMBRO]]) -> 0
N12: =SUM(FCJAN[[#This Row],[JANEIRO]:[DEZEMBRO]]) -> 0
A13: Dinheiro/Caixa/Cofre | B13: =SUM(B14:B19) -> 0 | C13: =SUM(C14:C19) -> 0 | D13: =SUM(D14:D19) -> 0 | E13: =SUM(E14:E19) -> 0 | F13: =SUM(F14:F19) -> 0 | G13: =SUM(G14:G19) -> 0 | H13: =SUM(H14:H19) -> 0 | I13: =SUM(I14:I19) -> 0 | ... N13: =SUM(N14:N19) -> 0
A14: Aplicação 1 | N14: =SUM(FCJAN[[#This Row],[JANEIRO]:[DEZEMBRO]]) -> 0
A15: Aplicação 2 | N15: =SUM(FCJAN[[#This Row],[JANEIRO]:[DEZEMBRO]]) -> 0
A16: Aplicação 3 | N16: =SUM(FCJAN[[#This Row],[JANEIRO]:[DEZEMBRO]]) -> 0
N17: =SUM(FCJAN[[#This Row],[JANEIRO]:[DEZEMBRO]]) -> 0
N18: =SUM(FCJAN[[#This Row],[JANEIRO]:[DEZEMBRO]]) -> 0
N19: =SUM(FCJAN[[#This Row],[JANEIRO]:[DEZEMBRO]]) -> 0
A20: Aplicações | B20: =SUM(B21:B26) -> 0 | C20: =SUM(C21:C26) -> 0 | D20: =SUM(D21:D26) -> 0 | E20: =SUM(E21:E26) -> 0 | F20: =SUM(F21:F26) -> 0 | G20: =SUM(G21:G26) -> 0 | H20: =SUM(H21:H26) -> 0 | I20: =SUM(I21:I26) -> 0 | ... N20: =SUM(N21:N26) -> 0
A21: Aplicação 1 | N21: =SUM(FCJAN[[#This Row],[JANEIRO]:[DEZEMBRO]]) -> 0
A22: Aplicação 2 | N22: =SUM(FCJAN[[#This Row],[JANEIRO]:[DEZEMBRO]]) -> 0
A23: Aplicação 3 | N23: =SUM(FCJAN[[#This Row],[JANEIRO]:[DEZEMBRO]]) -> 0
N24: =SUM(FCJAN[[#This Row],[JANEIRO]:[DEZEMBRO]]) -> 0
N25: =SUM(FCJAN[[#This Row],[JANEIRO]:[DEZEMBRO]]) -> 0
N26: =SUM(FCJAN[[#This Row],[JANEIRO]:[DEZEMBRO]]) -> 0
A28: ( + ) Entradas | B28: =SUM(B29:B39) -> 0 | C28: =SUM(C29:C39) -> 0 | D28: =SUM(D29:D39) -> 0 | E28: =SUM(E29:E39) -> 0 | F28: =SUM(F29:F39) -> 0 | G28: =SUM(G29:G39) -> 0 | H28: =SUM(H29:H39) -> 0 | I28: =SUM(I29:I39) -> 0 | ... N28: =SUM(N29:N39) -> 0
A29: Recebimento de Pix | N29: =SUM(FCJAN[[#This Row],[JANEIRO]:[DEZEMBRO]]) -> 0
A30: Recebimento de Dinheiro | N30: =SUM(FCJAN[[#This Row],[JANEIRO]:[DEZEMBRO]]) -> 0
A31: Recebimento de Cartão de Débito | N31: =SUM(FCJAN[[#This Row],[JANEIRO]:[DEZEMBRO]]) -> 0
A32: Recebimento de Cartão de Crédito | N32: =SUM(FCJAN[[#This Row],[JANEIRO]:[DEZEMBRO]]) -> 0
A33: Recebimento via Link de Pagamento | N33: =SUM(FCJAN[[#This Row],[JANEIRO]:[DEZEMBRO]]) -> 0
A34: Aporte Financeiro de Sócios | N34: =SUM(FCJAN[[#This Row],[JANEIRO]:[DEZEMBRO]]) -> 0
A35: Emprestimos bancários | N35: =SUM(FCJAN[[#This Row],[JANEIRO]:[DEZEMBRO]]) -> 0
A36: Outras Receitas não operacionais | N36: =SUM(FCJAN[[#This Row],[JANEIRO]:[DEZEMBRO]]) -> 0
N37: =SUM(FCJAN[[#This Row],[JANEIRO]:[DEZEMBRO]]) -> 0
N38: =SUM(FCJAN[[#This Row],[JANEIRO]:[DEZEMBRO]]) -> 0
N39: =SUM(FCJAN[[#This Row],[JANEIRO]:[DEZEMBRO]]) -> 0
A40: ( - ) Saídas | B40: =SUM(B41:B122) -> 0 | C40: =SUM(C41:C122) -> 0 | D40: =SUM(D41:D122) -> 0 | E40: =SUM(E41:E122) -> 0 | F40: =SUM(F41:F122) -> 0 | G40: =SUM(G41:G122) -> 0 | H40: =SUM(H41:H122) -> 0 | I40: =SUM(I41:I122) -> 0 | ... N40: =SUM(N41:N122) -> 0
A41: 13º 1ª Parcela | N41: =SUM(FCJAN[[#This Row],[JANEIRO]:[DEZEMBRO]]) -> 0
...

Sheet DRE
A1: DEMONSTRAÇÃO DE RESULTADO DE EXERCÍCIO
A2: DRE | B2: JANEIRO | C2: AV % JAN | D2: FEVEREIRO | E2: AV % FEV | F2: AH % FEV | G2: MARÇO | H2: AV % MAR | I2: AH % MAR | J2: ABRIL | K2: AV % ABR | L2: AH % ABR | M2: MAIO | N2: AV % MAI | O2: AH % MAI | P2: JUNHO | Q2: AV % JU | R2: AH % JUN | S2: JULHO | T2: AV % JUL | U2: AH % JUL | V2: AGOSTO | W2: AV % AGO | X2: AH % AGO | Y2: SETEMBRO | Z2: AV % SET | AA2: AH % SET | AB2: OUTUBRO | AC2: AV % OUT | AD2: AH % OUT | AE2: NOVEMBRO | AF2: AV % NOV | AG2: AH % NOV | AH2: DEZEMBRO | AI2: AV % DEZ | AJ2: AH % DEZ | AK2: TOTAL | AL2: AV % TT | AM2: MÉDIA
A3: (+) RECEITA TOTAL DE VENDAS | B3: =B4+B9+B14+B19+B24+B28 -> 0 | C3: =IFERROR(B3/$B$3,"") | D3: =D4+D9+D14+D19+D24+D28 -> 0 | E3: =IFERROR(D3/$D$3,"") | F3: =IFERROR((D3-B3)/B3,"") | G3: =G4+G9+G14+G19+G24+G28 -> 0 | H3: =IFERROR(G3/$G$3,"") | I3: =IFERROR((G3-D3)/D3,"") | J3: =J4+J9+J14+J19+J24+J28 -> 0 | K3: =IFERROR(J3/$J$3,"") | L3: =IFERROR((J3-G3)/G3,"") | M3: =M4+M9+M14+M19+M24+M28 -> 0 | N3: =IFERROR(M3/$M$3,"") | O3: =IFERROR((M3-J3)/J3,"") | P3: =P4+P9+P14+P19+P24+P28 -> 0 | Q3: =IFERROR(P3/$P$3,"") | R3: =IFERROR((P3-M3)/M3,"") | S3: =S4+S9+S14+S19+S24+S28 -> 0 | T3: =IFERROR(S3/$S$3,"") | U3: =IFERROR((S3-P3)/P3,"") | V3: =V4+V9+V14+V19+V24+V28 -> 0 | W3: =IFERROR(V3/$V$3,"") | X3: =IFERROR((V3-S3)/S3,"") | Y3: =Y4+Y9+Y14+Y19+Y24+Y28 -> 0 | Z3: =IFERROR(Y3/$Y$3,"") | AA3: =IFERROR((Y3-V3)/V3,"") | AB3: =AB4+AB9+AB14+AB19+AB24+AB28 -> 0 | AC3: =IFERROR(AB3/$AB$3,"") | AD3: =IFERROR((AB3-Y3)/Y3,"") | AE3: =AE4+AE9+AE14+AE19+AE24+AE28 -> 0 | AF3: =IFERROR(AE3/$AE$3,"") | AG3: =IFERROR((AE3-AB3)/AB3,"") | AH3: =AH4+AH9+AH14+AH19+AH24+AH28 -> 0 | AI3: =IFERROR(AH3/$AH$3,"") | AJ3: =IFERROR((AH3-AE3)/AE3,"") | AK3: =SUM(Tabela373[[#This Row],[JANEIRO]]+Tabela373[[#This Row],[FEVEREIRO]]+Tabela373[[#This Row],[MARÇO]]+Tabela373[[#This Row],[ABRIL]]+Tabela373[[#This Row],[MAIO]]+Tabela373[[#This Row],[JUNHO]]+Tabela373[[#This Row],[JULHO]]+Tabela373[[#This Row],[AGOSTO]]+Tabela373[[#This Row],[SETEMBRO]]+Tabela373[[#This Row],[NOVEMBRO]]+Tabela373[[#This Row],[DEZEMBRO]]) -> 0 | AL3: =IFERROR(AK3/$AK$3,"") | AM3: =AVERAGE(Tabela373[[#This Row],[JANEIRO]],Tabela373[[#This Row],[FEVEREIRO]],Tabela373[[#This Row],[MARÇO]],Tabela373[[#This Row],[ABRIL]],Tabela373[[#This Row],[MAIO]],Tabela373[[#This Row],[JUNHO]],Tabela373[[#This Row],[JULHO]],Tabela373[[#This Row],[AGOSTO]],Tabela373[[#This Row],[SETEMBRO]],Tabela373[[#This Row],[OUTUBRO]],Tabela373[[#This Row],[NOVEMBRO]],Tabela373[[#This Row],[DEZEMBRO]]) -> 0
A4: PRODUTOS | B4: =SUM(B5:B8) -> 0 | C4: =IFERROR(B4/$B$3,"") | D4: =SUM(D5:D8) -> 0 | E4: =IFERROR(D4/$D$3,"") | F4: =IFERROR((D4-B4)/B4,"") | G4: =SUM(G5:G8) -> 0 | H4: =IFERROR(G4/$G$3,"") | I4: =IFERROR((G4-D4)/D4,"") | J4: =SUM(J5:J8) -> 0 | K4: =IFERROR(J4/$J$3,"") | L4: =IFERROR((J4-G4)/G4,"") | M4: =SUM(M5:M8) -> 0 | N4: =IFERROR(M4/$M$3,"") | O4: =IFERROR((M4-J4)/J4,"") | P4: =SUM(P5:P8) -> 0 | Q4: =IFERROR(P4/$P$3,"") | R4: =IFERROR((P4-M4)/M4,"") | S4: =SUM(S5:S8) -> 0 | T4: =IFERROR(S4/$S$3,"") | U4: =IFERROR((S4-P4)/P4,"") | V4: =SUM(V5:V8) -> 0 | W4: =IFERROR(V4/$V$3,"") | X4: =IFERROR((V4-S4)/S4,"") | Y4: =SUM(Y5:Y8) -> 0 | Z4: =IFERROR(Y4/$Y$3,"") | AA4: =IFERROR((Y4-V4)/V4,"") | AB4: =SUM(AB5:AB8) -> 0 | AC4: =IFERROR(AB4/$AB$3,"") | AD4: =IFERROR((AB4-Y4)/Y4,"") | AE4: =SUM(AE5:AE8) -> 0 | AF4: =IFERROR(AE4/$AE$3,"") | AG4: =IFERROR((AE4-AB4)/AB4,"") | AH4: =SUM(AH5:AH8) -> 0 | AI4: =IFERROR(AH4/$AH$3,"") | AJ4: =IFERROR((AH4-AE4)/AE4,"") | AK4: =SUM(Tabela373[[#This Row],[JANEIRO]]+Tabela373[[#This Row],[FEVEREIRO]]+Tabela373[[#This Row],[MARÇO]]+Tabela373[[#This Row],[ABRIL]]+Tabela373[[#This Row],[MAIO]]+Tabela373[[#This Row],[JUNHO]]+Tabela373[[#This Row],[JULHO]]+Tabela373[[#This Row],[AGOSTO]]+Tabela373[[#This Row],[SETEMBRO]]+Tabela373[[#This Row],[NOVEMBRO]]+Tabela373[[#This Row],[DEZEMBRO]]) -> 0 | AL4: =IFERROR(AK4/$AK$3,"") | AM4: =AVERAGE(Tabela373[[#This Row],[JANEIRO]],Tabela373[[#This Row],[FEVEREIRO]],Tabela373[[#This Row],[MARÇO]],Tabela373[[#This Row],[ABRIL]],Tabela373[[#This Row],[MAIO]],Tabela373[[#This Row],[JUNHO]],Tabela373[[#This Row],[JULHO]],Tabela373[[#This Row],[AGOSTO]],Tabela373[[#This Row],[SETEMBRO]],Tabela373[[#This Row],[OUTUBRO]],Tabela373[[#This Row],[NOVEMBRO]],Tabela373[[#This Row],[DEZEMBRO]]) -> 0
A5: PRODUTO 1 | C5: =IFERROR(B5/$B$3,"") | E5: =IFERROR(D5/$D$3,"") | F5: =IFERROR((D5-B5)/B5,"") | H5: =IFERROR(G5/$G$3,"") | I5: =IFERROR((G5-D5)/D5,"") | K5: =IFERROR(J5/$J$3,"") | L5: =IFERROR((J5-G5)/G5,"") | N5: =IFERROR(M5/$M$3,"") | O5: =IFERROR((M5-J5)/J5,"") | Q5: =IFERROR(P5/$P$3,"") | R5: =IFERROR((P5-M5)/M5,"") | T5: =IFERROR(S5/$S$3,"") | U5: =IFERROR((S5-P5)/P5,"") | W5: =IFERROR(V5/$V$3,"") | X5: =IFERROR((V5-S5)/S5,"") | Z5: =IFERROR(Y5/$Y$3,"") | AA5: =IFERROR((Y5-V5)/V5,"") | AC5: =IFERROR(AB5/$AB$3,"") | AD5: =IFERROR((AB5-Y5)/Y5,"") | AF5: =IFERROR(AE5/$AE$3,"") | AG5: =IFERROR((AE5-AB5)/AB5,"") | AI5: =IFERROR(AH5/$AH$3,"") | AJ5: =IFERROR((AH5-AE5)/AE5,"") | AK5: =SUM(Tabela373[[#This Row],[JANEIRO]]+Tabela373[[#This Row],[FEVEREIRO]]+Tabela373[[#This Row],[MARÇO]]+Tabela373[[#This Row],[ABRIL]]+Tabela373[[#This Row],[MAIO]]+Tabela373[[#This Row],[JUNHO]]+Tabela373[[#This Row],[JULHO]]+Tabela373[[#This Row],[AGOSTO]]+Tabela373[[#This Row],[SETEMBRO]]+Tabela373[[#This Row],[NOVEMBRO]]+Tabela373[[#This Row],[DEZEMBRO]]) -> 0 | AL5: =IFERROR(AK5/$AK$3,"") | AM5: =AVERAGE(Tabela373[[#This Row],[JANEIRO]],Tabela373[[#This Row],[FEVEREIRO]],Tabela373[[#This Row],[MARÇO]],Tabela373[[#This Row],[ABRIL]],Tabela373[[#This Row],[MAIO]],Tabela373[[#This Row],[JUNHO]],Tabela373[[#This Row],[JULHO]],Tabela373[[#This Row],[AGOSTO]],Tabela373[[#This Row],[SETEMBRO]],Tabela373[[#This Row],[OUTUBRO]],Tabela373[[#This Row],[NOVEMBRO]],Tabela373[[#This Row],[DEZEMBRO]]) -> #DIV/0!
A6: PRODUTO 2 | C6: =IFERROR(B6/$B$3,"") | E6: =IFERROR(D6/$D$3,"") | F6: =IFERROR((D6-B6)/B6,"") | H6: =IFERROR(G6/$G$3,"") | I6: =IFERROR((G6-D6)/D6,"") | K6: =IFERROR(J6/$J$3,"") | L6: =IFERROR((J6-G6)/G6,"") | N6: =IFERROR(M6/$M$3,"") | O6: =IFERROR((M6-J6)/J6,"") | Q6: =IFERROR(P6/$P$3,"") | R6: =IFERROR((P6-M6)/M6,"") | T6: =IFERROR(S6/$S$3,"") | U6: =IFERROR((S6-P6)/P6,"") | W6: =IFERROR(V6/$V$3,"") | X6: =IFERROR((V6-S6)/S6,"") | Z6: =IFERROR(Y6/$Y$3,"") | AA6: =IFERROR((Y6-V6)/V6,"") | AC6: =IFERROR(AB6/$AB$3,"") | AD6: =IFERROR((AB6-Y6)/Y6,"") | AF6: =IFERROR(AE6/$AE$3,"") | AG6: =IFERROR((AE6-AB6)/AB6,"") | AI6: =IFERROR(AH6/$AH$3,"") | AJ6: =IFERROR((AH6-AE6)/AE6,"") | AK6: =SUM(Tabela373[[#This Row],[JANEIRO]]+Tabela373[[#This Row],[FEVEREIRO]]+Tabela373[[#This Row],[MARÇO]]+Tabela373[[#This Row],[ABRIL]]+Tabela373[[#This Row],[MAIO]]+Tabela373[[#This Row],[JUNHO]]+Tabela373[[#This Row],[JULHO]]+Tabela373[[#This Row],[AGOSTO]]+Tabela373[[#This Row],[SETEMBRO]]+Tabela373[[#This Row],[NOVEMBRO]]+Tabela373[[#This Row],[DEZEMBRO]]) -> 0 | AL6: =IFERROR(AK6/$AK$3,"") | AM6: =AVERAGE(Tabela373[[#This Row],[JANEIRO]],Tabela373[[#This Row],[FEVEREIRO]],Tabela373[[#This Row],[MARÇO]],Tabela373[[#This Row],[ABRIL]],Tabela373[[#This Row],[MAIO]],Tabela373[[#This Row],[JUNHO]],Tabela373[[#This Row],[JULHO]],Tabela373[[#This Row],[AGOSTO]],Tabela373[[#This Row],[SETEMBRO]],Tabela373[[#This Row],[OUTUBRO]],Tabela373[[#This Row],[NOVEMBRO]],Tabela373[[#This Row],[DEZEMBRO]]) -> #DIV/0!
A7: PRODUTO 3 | C7: =IFERROR(B7/$B$3,"") | E7: =IFERROR(D7/$D$3,"") | F7: =IFERROR((D7-B7)/B7,"") | H7: =IFERROR(G7/$G$3,"") | I7: =IFERROR((G7-D7)/D7,"") | K7: =IFERROR(J7/$J$3,"") | L7: =IFERROR((J7-G7)/G7,"") | N7: =IFERROR(M7/$M$3,"") | O7: =IFERROR((M7-J7)/J7,"") | Q7: =IFERROR(P7/$P$3,"") | R7: =IFERROR((P7-M7)/M7,"") | T7: =IFERROR(S7/$S$3,"") | U7: =IFERROR((S7-P7)/P7,"") | W7: =IFERROR(V7/$V$3,"") | X7: =IFERROR((V7-S7)/S7,"") | Z7: =IFERROR(Y7/$Y$3,"") | AA7: =IFERROR((Y7-V7)/V7,"") | AC7: =IFERROR(AB7/$AB$3,"") | AD7: =IFERROR((AB7-Y7)/Y7,"") | AF7: =IFERROR(AE7/$AE$3,"") | AG7: =IFERROR((AE7-AB7)/AB7,"") | AI7: =IFERROR(AH7/$AH$3,"") | AJ7: =IFERROR((AH7-AE7)/AE7,"") | AK7: =SUM(Tabela373[[#This Row],[JANEIRO]]+Tabela373[[#This Row],[FEVEREIRO]]+Tabela373[[#This Row],[MARÇO]]+Tabela373[[#This Row],[ABRIL]]+Tabela373[[#This Row],[MAIO]]+Tabela373[[#This Row],[JUNHO]]+Tabela373[[#This Row],[JULHO]]+Tabela373[[#This Row],[AGOSTO]]+Tabela373[[#This Row],[SETEMBRO]]+Tabela373[[#This Row],[NOVEMBRO]]+Tabela373[[#This Row],[DEZEMBRO]]) -> 0 | AL7: =IFERROR(AK7/$AK$3,"") | AM7: =AVERAGE(Tabela373[[#This Row],[JANEIRO]],Tabela373[[#This Row],[FEVEREIRO]],Tabela373[[#This Row],[MARÇO]],Tabela373[[#This Row],[ABRIL]],Tabela373[[#This Row],[MAIO]],Tabela373[[#This Row],[JUNHO]],Tabela373[[#This Row],[JULHO]],Tabela373[[#This Row],[AGOSTO]],Tabela373[[#This Row],[SETEMBRO]],Tabela373[[#This Row],[OUTUBRO]],Tabela373[[#This Row],[NOVEMBRO]],Tabela373[[#This Row],[DEZEMBRO]]) -> #DIV/0!
C8: =IFERROR(B8/$B$3,"") | E8: =IFERROR(D8/$D$3,"") | F8: =IFERROR((D8-B8)/B8,"") | H8: =IFERROR(G8/$G$3,"") | I8: =IFERROR((G8-D8)/D8,"") | K8: =IFERROR(J8/$J$3,"") | L8: =IFERROR((J8-G8)/G8,"") | N8: =IFERROR(M8/$M$3,"") | O8: =IFERROR((M8-J8)/J8,"") | Q8: =IFERROR(P8/$P$3,"") | R8: =IFERROR((P8-M8)/M8,"") | T8: =IFERROR(S8/$S$3,"") | U8: =IFERROR((S8-P8)/P8,"") | W8: =IFERROR(V8/$V$3,"") | X8: =IFERROR((V8-S8)/S8,"") | Z8: =IFERROR(Y8/$Y$3,"") | AA8: =IFERROR((Y8-V8)/V8,"") | AC8: =IFERROR(AB8/$AB$3,"") | AD8: =IFERROR((AB8-Y8)/Y8,"") | AF8: =IFERROR(AE8/$AE$3,"") | AG8: =IFERROR((AE8-AB8)/AB8,"") | AI8: =IFERROR(AH8/$AH$3,"") | AJ8: =IFERROR((AH8-AE8)/AE8,"") | AK8: =SUM(Tabela373[[#This Row],[JANEIRO]]+Tabela373[[#This Row],[FEVEREIRO]]+Tabela373[[#This Row],[MARÇO]]+Tabela373[[#This Row],[ABRIL]]+Tabela373[[#This Row],[MAIO]]+Tabela373[[#This Row],[JUNHO]]+Tabela373[[#This Row],[JULHO]]+Tabela373[[#This Row],[AGOSTO]]+Tabela373[[#This Row],[SETEMBRO]]+Tabela373[[#This Row],[NOVEMBRO]]+Tabela373[[#This Row],[DEZEMBRO]]) -> 0 | AL8: =IFERROR(AK8/$AK$3,"") | AM8: =AVERAGE(Tabela373[[#This Row],[JANEIRO]],Tabela373[[#This Row],[FEVEREIRO]],Tabela373[[#This Row],[MARÇO]],Tabela373[[#This Row],[ABRIL]],Tabela373[[#This Row],[MAIO]],Tabela373[[#This Row],[JUNHO]],Tabela373[[#This Row],[JULHO]],Tabela373[[#This Row],[AGOSTO]],Tabela373[[#This Row],[SETEMBRO]],Tabela373[[#This Row],[OUTUBRO]],Tabela373[[#This Row],[NOVEMBRO]],Tabela373[[#This Row],[DEZEMBRO]]) -> #DIV/0!
A9: LINHA DE PRODUTOS | B9: =SUM(B10:B13) -> 0 | C9: =IFERROR(B9/$B$3,"") | D9: =SUM(D10:D13) -> 0 | E9: =IFERROR(D9/$D$3,"") | F9: =IFERROR((D9-B9)/B9,"") | G9: =SUM(G10:G13) -> 0 | H9: =IFERROR(G9/$G$3,"") | I9: =IFERROR((G9-D9)/D9,"") | J9: =SUM(J10:J13) -> 0 | K9: =IFERROR(J9/$J$3,"") | L9: =IFERROR((J9-G9)/G9,"") | M9: =SUM(M10:M13) -> 0 | N9: =IFERROR(M9/$M$3,"") | O9: =IFERROR((M9-J9)/J9,"") | P9: =SUM(P10:P13) -> 0 | Q9: =IFERROR(P9/$P$3,"") | R9: =IFERROR((P9-M9)/M9,"") | S9: =SUM(S10:S13) -> 0 | T9: =IFERROR(S9/$S$3,"") | U9: =IFERROR((S9-P9)/P9,"") | V9: =SUM(V10:V13) -> 0 | W9: =IFERROR(V9/$V$3,"") | X9: =IFERROR((V9-S9)/S9,"") | Y9: =SUM(Y10:Y13) -> 0 | Z9: =IFERROR(Y9/$Y$3,"") | AA9: =IFERROR((Y9-V9)/V9,"") | AB9: =SUM(AB10:AB13) -> 0 | AC9: =IFERROR(AB9/$AB$3,"") | AD9: =IFERROR((AB9-Y9)/Y9,"") | AE9: =SUM(AE10:AE13) -> 0 | AF9: =IFERROR(AE9/$AE$3,"") | AG9: =IFERROR((AE9-AB9)/AB9,"") | AH9: =SUM(AH10:AH13) -> 0 | AI9: =IFERROR(AH9/$AH$3,"") | AJ9: =IFERROR((AH9-AE9)/AE9,"") | AK9: =SUM(Tabela373[[#This Row],[JANEIRO]]+Tabela373[[#This Row],[FEVEREIRO]]+Tabela373[[#This Row],[MARÇO]]+Tabela373[[#This Row],[ABRIL]]+Tabela373[[#This Row],[MAIO]]+Tabela373[[#This Row],[JUNHO]]+Tabela373[[#This Row],[JULHO]]+Tabela373[[#This Row],[AGOSTO]]+Tabela373[[#This Row],[SETEMBRO]]+Tabela373[[#This Row],[NOVEMBRO]]+Tabela373[[#This Row],[DEZEMBRO]]) -> 0 | AL9: =IFERROR(AK9/$AK$3,"") | AM9: =AVERAGE(Tabela373[[#This Row],[JANEIRO]],Tabela373[[#This Row],[FEVEREIRO]],Tabela373[[#This Row],[MARÇO]],Tabela373[[#This Row],[ABRIL]],Tabela373[[#This Row],[MAIO]],Tabela373[[#This Row],[JUNHO]],Tabela373[[#This Row],[JULHO]],Tabela373[[#This Row],[AGOSTO]],Tabela373[[#This Row],[SETEMBRO]],Tabela373[[#This Row],[OUTUBRO]],Tabela373[[#This Row],[NOVEMBRO]],Tabela373[[#This Row],[DEZEMBRO]]) -> 0
A10: LINHA 1 | C10: =IFERROR(B10/$B$3,"") | E10: =IFERROR(D10/$D$3,"") | F10: =IFERROR((D10-B10)/B10,"") | H10: =IFERROR(G10/$G$3,"") | I10: =IFERROR((G10-D10)/D10,"") | K10: =IFERROR(J10/$J$3,"") | L10: =IFERROR((J10-G10)/G10,"") | N10: =IFERROR(M10/$M$3,"") | O10: =IFERROR((M10-J10)/J10,"") | Q10: =IFERROR(P10/$P$3,"") | R10: =IFERROR((P10-M10)/M10,"") | T10: =IFERROR(S10/$S$3,"") | U10: =IFERROR((S10-P10)/P10,"") | W10: =IFERROR(V10/$V$3,"") | X10: =IFERROR((V10-S10)/S10,"") | Z10: =IFERROR(Y10/$Y$3,"") | AA10: =IFERROR((Y10-V10)/V10,"") | AC10: =IFERROR(AB10/$AB$3,"") | AD10: =IFERROR((AB10-Y10)/Y10,"") | AF10: =IFERROR(AE10/$AE$3,"") | AG10: =IFERROR((AE10-AB10)/AB10,"") | AI10: =IFERROR(AH10/$AH$3,"") | AJ10: =IFERROR((AH10-AE10)/AE10,"") | AK10: =SUM(Tabela373[[#This Row],[JANEIRO]]+Tabela373[[#This Row],[FEVEREIRO]]+Tabela373[[#This Row],[MARÇO]]+Tabela373[[#This Row],[ABRIL]]+Tabela373[[#This Row],[MAIO]]+Tabela373[[#This Row],[JUNHO]]+Tabela373[[#This Row],[JULHO]]+Tabela373[[#This Row],[AGOSTO]]+Tabela373[[#This Row],[SETEMBRO]]+Tabela373[[#This Row],[NOVEMBRO]]+Tabela373[[#This Row],[DEZEMBRO]]) -> 0 | AL10: =IFERROR(AK10/$AK$3,"") | AM10: =AVERAGE(Tabela373[[#This Row],[JANEIRO]],Tabela373[[#This Row],[FEVEREIRO]],Tabela373[[#This Row],[MARÇO]],Tabela373[[#This Row],[ABRIL]],Tabela373[[#This Row],[MAIO]],Tabela373[[#This Row],[JUNHO]],Tabela373[[#This Row],[JULHO]],Tabela373[[#This Row],[AGOSTO]],Tabela373[[#This Row],[SETEMBRO]],Tabela373[[#This Row],[OUTUBRO]],Tabela373[[#This Row],[NOVEMBRO]],Tabela373[[#This Row],[DEZEMBRO]]) -> #DIV/0!
A11: LINHA 2 | C11: =IFERROR(B11/$B$3,"") | E11: =IFERROR(D11/$D$3,"") | F11: =IFERROR((D11-B11)/B11,"") | H11: =IFERROR(G11/$G$3,"") | I11: =IFERROR((G11-D11)/D11,"") | K11: =IFERROR(J11/$J$3,"") | L11: =IFERROR((J11-G11)/G11,"") | N11: =IFERROR(M11/$M$3,"") | O11: =IFERROR((M11-J11)/J11,"") | Q11: =IFERROR(P11/$P$3,"") | R11: =IFERROR((P11-M11)/M11,"") | T11: =IFERROR(S11/$S$3,"") | U11: =IFERROR((S11-P11)/P11,"") | W11: =IFERROR(V11/$V$3,"") | X11: =IFERROR((V11-S11)/S11,"") | Z11: =IFERROR(Y11/$Y$3,"") | AA11: =IFERROR((Y11-V11)/V11,"") | AC11: =IFERROR(AB11/$AB$3,"") | AD11: =IFERROR((AB11-Y11)/Y11,"") | AF11: =IFERROR(AE11/$AE$3,"") | AG11: =IFERROR((AE11-AB11)/AB11,"") | AI11: =IFERROR(AH11/$AH$3,"") | AJ11: =IFERROR((AH11-AE11)/AE11,"") | AK11: =SUM(Tabela373[[#This Row],[JANEIRO]]+Tabela373[[#This Row],[FEVEREIRO]]+Tabela373[[#This Row],[MARÇO]]+Tabela373[[#This Row],[ABRIL]]+Tabela373[[#This Row],[MAIO]]+Tabela373[[#This Row],[JUNHO]]+Tabela373[[#This Row],[JULHO]]+Tabela373[[#This Row],[AGOSTO]]+Tabela373[[#This Row],[SETEMBRO]]+Tabela373[[#This Row],[NOVEMBRO]]+Tabela373[[#This Row],[DEZEMBRO]]) -> 0 | AL11: =IFERROR(AK11/$AK$3,"") | AM11: =AVERAGE(Tabela373[[#This Row],[JANEIRO]],Tabela373[[#This Row],[FEVEREIRO]],Tabela373[[#This Row],[MARÇO]],Tabela373[[#This Row],[ABRIL]],Tabela373[[#This Row],[MAIO]],Tabela373[[#This Row],[JUNHO]],Tabela373[[#This Row],[JULHO]],Tabela373[[#This Row],[AGOSTO]],Tabela373[[#This Row],[SETEMBRO]],Tabela373[[#This Row],[OUTUBRO]],Tabela373[[#This Row],[NOVEMBRO]],Tabela373[[#This Row],[DEZEMBRO]]) -> #DIV/0!
A12: LINHA 3 | C12: =IFERROR(B12/$B$3,"") | E12: =IFERROR(D12/$D$3,"") | F12: =IFERROR((D12-B12)/B12,"") | H12: =IFERROR(G12/$G$3,"") | I12: =IFERROR((G12-D12)/D12,"") | K12: =IFERROR(J12/$J$3,"") | L12: =IFERROR((J12-G12)/G12,"") | N12: =IFERROR(M12/$M$3,"") | O12: =IFERROR((M12-J12)/J12,"") | Q12: =IFERROR(P12/$P$3,"") | R12: =IFERROR((P12-M12)/M12,"") | T12: =IFERROR(S12/$S$3,"") | U12: =IFERROR((S12-P12)/P12,"") | W12: =IFERROR(V12/$V$3,"") | X12: =IFERROR((V12-S12)/S12,"") | Z12: =IFERROR(Y12/$Y$3,"") | AA12: =IFERROR((Y12-V12)/V12,"") | AC12: =IFERROR(AB12/$AB$3,"") | AD12: =IFERROR((AB12-Y12)/Y12,"") | AF12: =IFERROR(AE12/$AE$3,"") | AG12: =IFERROR((AE12-AB12)/AB12,"") | AI12: =IFERROR(AH12/$AH$3,"") | AJ12: =IFERROR((AH12-AE12)/AE12,"") | AK12: =SUM(Tabela373[[#This Row],[JANEIRO]]+Tabela373[[#This Row],[FEVEREIRO]]+Tabela373[[#This Row],[MARÇO]]+Tabela373[[#This Row],[ABRIL]]+Tabela373[[#This Row],[MAIO]]+Tabela373[[#This Row],[JUNHO]]+Tabela373[[#This Row],[JULHO]]+Tabela373[[#This Row],[AGOSTO]]+Tabela373[[#This Row],[SETEMBRO]]+Tabela373[[#This Row],[NOVEMBRO]]+Tabela373[[#This Row],[DEZEMBRO]]) -> 0 | AL12: =IFERROR(AK12/$AK$3,"") | AM12: =AVERAGE(Tabela373[[#This Row],[JANEIRO]],Tabela373[[#This Row],[FEVEREIRO]],Tabela373[[#This Row],[MARÇO]],Tabela373[[#This Row],[ABRIL]],Tabela373[[#This Row],[MAIO]],Tabela373[[#This Row],[JUNHO]],Tabela373[[#This Row],[JULHO]],Tabela373[[#This Row],[AGOSTO]],Tabela373[[#This Row],[SETEMBRO]],Tabela373[[#This Row],[OUTUBRO]],Tabela373[[#This Row],[NOVEMBRO]],Tabela373[[#This Row],[DEZEMBRO]]) -> #DIV/0!
C13: =IFERROR(B13/$B$3,"") | E13: =IFERROR(D13/$D$3,"") | F13: =IFERROR((D13-B13)/B13,"") | H13: =IFERROR(G13/$G$3,"") | I13: =IFERROR((G13-D13)/D13,"") | K13: =IFERROR(J13/$J$3,"") | L13: =IFERROR((J13-G13)/G13,"") | N13: =IFERROR(M13/$M$3,"") | O13: =IFERROR((M13-J13)/J13,"") | Q13: =IFERROR(P13/$P$3,"") | R13: =IFERROR((P13-M13)/M13,"") | T13: =IFERROR(S13/$S$3,"") | U13: =IFERROR((S13-P13)/P13,"") | W13: =IFERROR(V13/$V$3,"") | X13: =IFERROR((V13-S13)/S13,"") | Z13: =IFERROR(Y13/$Y$3,"") | AA13: =IFERROR((Y13-V13)/V13,"") | AC13: =IFERROR(AB13/$AB$3,"") | AD13: =IFERROR((AB13-Y13)/Y13,"") | AF13: =IFERROR(AE13/$AE$3,"") | AG13: =IFERROR((AE13-AB13)/AB13,"") | AI13: =IFERROR(AH13/$AH$3,"") | AJ13: =IFERROR((AH13-AE13)/AE13,"") | AK13: =SUM(Tabela373[[#This Row],[JANEIRO]]+Tabela373[[#This Row],[FEVEREIRO]]+Tabela373[[#This Row],[MARÇO]]+Tabela373[[#This Row],[ABRIL]]+Tabela373[[#This Row],[MAIO]]+Tabela373[[#This Row],[JUNHO]]+Tabela373[[#This Row],[JULHO]]+Tabela373[[#This Row],[AGOSTO]]+Tabela373[[#This Row],[SETEMBRO]]+Tabela373[[#This Row],[NOVEMBRO]]+Tabela373[[#This Row],[DEZEMBRO]]) -> 0 | AL13: =IFERROR(AK13/$AK$3,"") | AM13: =AVERAGE(Tabela373[[#This Row],[JANEIRO]],Tabela373[[#This Row],[FEVEREIRO]],Tabela373[[#This Row],[MARÇO]],Tabela373[[#This Row],[ABRIL]],Tabela373[[#This Row],[MAIO]],Tabela373[[#This Row],[JUNHO]],Tabela373[[#This Row],[JULHO]],Tabela373[[#This Row],[AGOSTO]],Tabela373[[#This Row],[SETEMBRO]],Tabela373[[#This Row],[OUTUBRO]],Tabela373[[#This Row],[NOVEMBRO]],Tabela373[[#This Row],[DEZEMBRO]]) -> #DIV/0!
A14: SERVIÇOS | B14: =SUM(B15:B18) -> 0 | C14: =IFERROR(B14/$B$3,"") | D14: =SUM(D15:D18) -> 0 | E14: =IFERROR(D14/$D$3,"") | F14: =IFERROR((D14-B14)/B14,"") | G14: =SUM(G15:G18) -> 0 | H14: =IFERROR(G14/$G$3,"") | I14: =IFERROR((G14-D14)/D14,"") | J14: =SUM(J15:J18) -> 0 | K14: =IFERROR(J14/$J$3,"") | L14: =IFERROR((J14-G14)/G14,"") | M14: =SUM(M15:M18) -> 0 | N14: =IFERROR(M14/$M$3,"") | O14: =IFERROR((M14-J14)/J14,"") | P14: =SUM(P15:P18) -> 0 | Q14: =IFERROR(P14/$P$3,"") | R14: =IFERROR((P14-M14)/M14,"") | S14: =SUM(S15:S18) -> 0 | T14: =IFERROR(S14/$S$3,"") | U14: =IFERROR((S14-P14)/P14,"") | V14: =SUM(V15:V18) -> 0 | W14: =IFERROR(V14/$V$3,"") | X14: =IFERROR((V14-S14)/S14,"") | Y14: =SUM(Y15:Y18) -> 0 | Z14: =IFERROR(Y14/$Y$3,"") | AA14: =IFERROR((Y14-V14)/V14,"") | AB14: =SUM(AB15:AB18) -> 0 | AC14: =IFERROR(AB14/$AB$3,"") | AD14: =IFERROR((AB14-Y14)/Y14,"") | AE14: =SUM(AE15:AE18) -> 0 | AF14: =IFERROR(AE14/$AE$3,"") | AG14: =IFERROR((AE14-AB14)/AB14,"") | AH14: =SUM(AH15:AH18) -> 0 | AI14: =IFERROR(AH14/$AH$3,"") | AJ14: =IFERROR((AH14-AE14)/AE14,"") | AK14: =SUM(Tabela373[[#This Row],[JANEIRO]]+Tabela373[[#This Row],[FEVEREIRO]]+Tabela373[[#This Row],[MARÇO]]+Tabela373[[#This Row],[ABRIL]]+Tabela373[[#This Row],[MAIO]]+Tabela373[[#This Row],[JUNHO]]+Tabela373[[#This Row],[JULHO]]+Tabela373[[#This Row],[AGOSTO]]+Tabela373[[#This Row],[SETEMBRO]]+Tabela373[[#This Row],[NOVEMBRO]]+Tabela373[[#This Row],[DEZEMBRO]]) -> 0 | AL14: =IFERROR(AK14/$AK$3,"") | AM14: =AVERAGE(Tabela373[[#This Row],[JANEIRO]],Tabela373[[#This Row],[FEVEREIRO]],Tabela373[[#This Row],[MARÇO]],Tabela373[[#This Row],[ABRIL]],Tabela373[[#This Row],[MAIO]],Tabela373[[#This Row],[JUNHO]],Tabela373[[#This Row],[JULHO]],Tabela373[[#This Row],[AGOSTO]],Tabela373[[#This Row],[SETEMBRO]],Tabela373[[#This Row],[OUTUBRO]],Tabela373[[#This Row],[NOVEMBRO]],Tabela373[[#This Row],[DEZEMBRO]]) -> 0
A15: SERVIÇO 1 | C15: =IFERROR(B15/$B$3,"") | E15: =IFERROR(D15/$D$3,"") | F15: =IFERROR((D15-B15)/B15,"") | H15: =IFERROR(G15/$G$3,"") | I15: =IFERROR((G15-D15)/D15,"") | K15: =IFERROR(J15/$J$3,"") | L15: =IFERROR((J15-G15)/G15,"") | N15: =IFERROR(M15/$M$3,"") | O15: =IFERROR((M15-J15)/J15,"") | Q15: =IFERROR(P15/$P$3,"") | R15: =IFERROR((P15-M15)/M15,"") | T15: =IFERROR(S15/$S$3,"") | U15: =IFERROR((S15-P15)/P15,"") | W15: =IFERROR(V15/$V$3,"") | X15: =IFERROR((V15-S15)/S15,"") | Z15: =IFERROR(Y15/$Y$3,"") | AA15: =IFERROR((Y15-V15)/V15,"") | AC15: =IFERROR(AB15/$AB$3,"") | AD15: =IFERROR((AB15-Y15)/Y15,"") | AF15: =IFERROR(AE15/$AE$3,"") | AG15: =IFERROR((AE15-AB15)/AB15,"") | AI15: =IFERROR(AH15/$AH$3,"") | AJ15: =IFERROR((AH15-AE15)/AE15,"") | AK15: =SUM(Tabela373[[#This Row],[JANEIRO]]+Tabela373[[#This Row],[FEVEREIRO]]+Tabela373[[#This Row],[MARÇO]]+Tabela373[[#This Row],[ABRIL]]+Tabela373[[#This Row],[MAIO]]+Tabela373[[#This Row],[JUNHO]]+Tabela373[[#This Row],[JULHO]]+Tabela373[[#This Row],[AGOSTO]]+Tabela373[[#This Row],[SETEMBRO]]+Tabela373[[#This Row],[NOVEMBRO]]+Tabela373[[#This Row],[DEZEMBRO]]) -> 0 | AL15: =IFERROR(AK15/$AK$3,"") | AM15: =AVERAGE(Tabela373[[#This Row],[JANEIRO]],Tabela373[[#This Row],[FEVEREIRO]],Tabela373[[#This Row],[MARÇO]],Tabela373[[#This Row],[ABRIL]],Tabela373[[#This Row],[MAIO]],Tabela373[[#This Row],[JUNHO]],Tabela373[[#This Row],[JULHO]],Tabela373[[#This Row],[AGOSTO]],Tabela373[[#This Row],[SETEMBRO]],Tabela373[[#This Row],[OUTUBRO]],Tabela373[[#This Row],[NOVEMBRO]],Tabela373[[#This Row],[DEZEMBRO]]) -> #DIV/0!
A16: SERVIÇO 2 | C16: =IFERROR(B16/$B$3,"") | E16: =IFERROR(D16/$D$3,"") | F16: =IFERROR((D16-B16)/B16,"") | H16: =IFERROR(G16/$G$3,"") | I16: =IFERROR((G16-D16)/D16,"") | K16: =IFERROR(J16/$J$3,"") | L16: =IFERROR((J16-G16)/G16,"") | N16: =IFERROR(M16/$M$3,"") | O16: =IFERROR((M16-J16)/J16,"") | Q16: =IFERROR(P16/$P$3,"") | R16: =IFERROR((P16-M16)/M16,"") | T16: =IFERROR(S16/$S$3,"") | U16: =IFERROR((S16-P16)/P16,"") | W16: =IFERROR(V16/$V$3,"") | X16: =IFERROR((V16-S16)/S16,"") | Z16: =IFERROR(Y16/$Y$3,"") | AA16: =IFERROR((Y16-V16)/V16,"") | AC16: =IFERROR(AB16/$AB$3,"") | AD16: =IFERROR((AB16-Y16)/Y16,"") | AF16: =IFERROR(AE16/$AE$3,"") | AG16: =IFERROR((AE16-AB16)/AB16,"") | AI16: =IFERROR(AH16/$AH$3,"") | AJ16: =IFERROR((AH16-AE16)/AE16,"") | AK16: =SUM(Tabela373[[#This Row],[JANEIRO]]+Tabela373[[#This Row],[FEVEREIRO]]+Tabela373[[#This Row],[MARÇO]]+Tabela373[[#This Row],[ABRIL]]+Tabela373[[#This Row],[MAIO]]+Tabela373[[#This Row],[JUNHO]]+Tabela373[[#This Row],[JULHO]]+Tabela373[[#This Row],[AGOSTO]]+Tabela373[[#This Row],[SETEMBRO]]+Tabela373[[#This Row],[NOVEMBRO]]+Tabela373[[#This Row],[DEZEMBRO]]) -> 0 | AL16: =IFERROR(AK16/$AK$3,"") | AM16: =AVERAGE(Tabela373[[#This Row],[JANEIRO]],Tabela373[[#This Row],[FEVEREIRO]],Tabela373[[#This Row],[MARÇO]],Tabela373[[#This Row],[ABRIL]],Tabela373[[#This Row],[MAIO]],Tabela373[[#This Row],[JUNHO]],Tabela373[[#This Row],[JULHO]],Tabela373[[#This Row],[AGOSTO]],Tabela373[[#This Row],[SETEMBRO]],Tabela373[[#This Row],[OUTUBRO]],Tabela373[[#This Row],[NOVEMBRO]],Tabela373[[#This Row],[DEZEMBRO]]) -> #DIV/0!
A17: SERVIÇO 3 | C17: =IFERROR(B17/$B$3,"") | E17: =IFERROR(D17/$D$3,"") | F17: =IFERROR((D17-B17)/B17,"") | H17: =IFERROR(G17/$G$3,"") | I17: =IFERROR((G17-D17)/D17,"") | K17: =IFERROR(J17/$J$3,"") | L17: =IFERROR((J17-G17)/G17,"") | N17: =IFERROR(M17/$M$3,"") | O17: =IFERROR((M17-J17)/J17,"") | Q17: =IFERROR(P17/$P$3,"") | R17: =IFERROR((P17-M17)/M17,"") | T17: =IFERROR(S17/$S$3,"") | U17: =IFERROR((S17-P17)/P17,"") | W17: =IFERROR(V17/$V$3,"") | X17: =IFERROR((V17-S17)/S17,"") | Z17: =IFERROR(Y17/$Y$3,"") | AA17: =IFERROR((Y17-V17)/V17,"") | AC17: =IFERROR(AB17/$AB$3,"") | AD17: =IFERROR((AB17-Y17)/Y17,"") | AF17: =IFERROR(AE17/$AE$3,"") | AG17: =IFERROR((AE17-AB17)/AB17,"") | AI17: =IFERROR(AH17/$AH$3,"") | AJ17: =IFERROR((AH17-AE17)/AE17,"") | AK17: =SUM(Tabela373[[#This Row],[JANEIRO]]+Tabela373[[#This Row],[FEVEREIRO]]+Tabela373[[#This Row],[MARÇO]]+Tabela373[[#This Row],[ABRIL]]+Tabela373[[#This Row],[MAIO]]+Tabela373[[#This Row],[JUNHO]]+Tabela373[[#This Row],[JULHO]]+Tabela373[[#This Row],[AGOSTO]]+Tabela373[[#This Row],[SETEMBRO]]+Tabela373[[#This Row],[NOVEMBRO]]+Tabela373[[#This Row],[DEZEMBRO]]) -> 0 | AL17: =IFERROR(AK17/$AK$3,"") | AM17: =AVERAGE(Tabela373[[#This Row],[JANEIRO]],Tabela373[[#This Row],[FEVEREIRO]],Tabela373[[#This Row],[MARÇO]],Tabela373[[#This Row],[ABRIL]],Tabela373[[#This Row],[MAIO]],Tabela373[[#This Row],[JUNHO]],Tabela373[[#This Row],[JULHO]],Tabela373[[#This Row],[AGOSTO]],Tabela373[[#This Row],[SETEMBRO]],Tabela373[[#This Row],[OUTUBRO]],Tabela373[[#This Row],[NOVEMBRO]],Tabela373[[#This Row],[DEZEMBRO]]) -> #DIV/0!
C18: =IFERROR(B18/$B$3,"") | E18: =IFERROR(D18/$D$3,"") | F18: =IFERROR((D18-B18)/B18,"") | H18: =IFERROR(G18/$G$3,"") | I18: =IFERROR((G18-D18)/D18,"") | K18: =IFERROR(J18/$J$3,"") | L18: =IFERROR((J18-G18)/G18,"") | N18: =IFERROR(M18/$M$3,"") | O18: =IFERROR((M18-J18)/J18,"") | Q18: =IFERROR(P18/$P$3,"") | R18: =IFERROR((P18-M18)/M18,"") | T18: =IFERROR(S18/$S$3,"") | U18: =IFERROR((S18-P18)/P18,"") | W18: =IFERROR(V18/$V$3,"") | X18: =IFERROR((V18-S18)/S18,"") | Z18: =IFERROR(Y18/$Y$3,"") | AA18: =IFERROR((Y18-V18)/V18,"") | AC18: =IFERROR(AB18/$AB$3,"") | AD18: =IFERROR((AB18-Y18)/Y18,"") | AF18: =IFERROR(AE18/$AE$3,"") | AG18: =IFERROR((AE18-AB18)/AB18,"") | AI18: =IFERROR(AH18/$AH$3,"") | AJ18: =IFERROR((AH18-AE18)/AE18,"") | AK18: =SUM(Tabela373[[#This Row],[JANEIRO]]+Tabela373[[#This Row],[FEVEREIRO]]+Tabela373[[#This Row],[MARÇO]]+Tabela373[[#This Row],[ABRIL]]+Tabela373[[#This Row],[MAIO]]+Tabela373[[#This Row],[JUNHO]]+Tabela373[[#This Row],[JULHO]]+Tabela373[[#This Row],[AGOSTO]]+Tabela373[[#This Row],[SETEMBRO]]+Tabela373[[#This Row],[NOVEMBRO]]+Tabela373[[#This Row],[DEZEMBRO]]) -> 0 | AL18: =IFERROR(AK18/$AK$3,"") | AM18: =AVERAGE(Tabela373[[#This Row],[JANEIRO]],Tabela373[[#This Row],[FEVEREIRO]],Tabela373[[#This Row],[MARÇO]],Tabela373[[#This Row],[ABRIL]],Tabela373[[#This Row],[MAIO]],Tabela373[[#This Row],[JUNHO]],Tabela373[[#This Row],[JULHO]],Tabela373[[#This Row],[AGOSTO]],Tabela373[[#This Row],[SETEMBRO]],Tabela373[[#This Row],[OUTUBRO]],Tabela373[[#This Row],[NOVEMBRO]],Tabela373[[#This Row],[DEZEMBRO]]) -> #DIV/0!
A19: CANAL DE VENDAS | B19: =SUM(B20:B23) -> 0 | C19: =IFERROR(B19/$B$3,"") | D19: =SUM(D20:D23) -> 0 | E19: =IFERROR(D19/$D$3,"") | F19: =IFERROR((D19-B19)/B19,"") | G19: =SUM(G20:G23) -> 0 | H19: =IFERROR(G19/$G$3,"") | I19: =IFERROR((G19-D19)/D19,"") | J19: =SUM(J20:J23) -> 0 | K19: =IFERROR(J19/$J$3,"") | L19: =IFERROR((J19-G19)/G19,"") | M19: =SUM(M20:M23) -> 0 | N19: =IFERROR(M19/$M$3,"") | O19: =IFERROR((M19-J19)/J19,"") | P19: =SUM(P20:P23) -> 0 | Q19: =IFERROR(P19/$P$3,"") | R19: =IFERROR((P19-M19)/M19,"") | S19: =SUM(S20:S23) -> 0 | T19: =IFERROR(S19/$S$3,"") | U19: =IFERROR((S19-P19)/P19,"") | V19: =SUM(V20:V23) -> 0 | W19: =IFERROR(V19/$V$3,"") | X19: =IFERROR((V19-S19)/S19,"") | Y19: =SUM(Y20:Y23) -> 0 | Z19: =IFERROR(Y19/$Y$3,"") | AA19: =IFERROR((Y19-V19)/V19,"") | AB19: =SUM(AB20:AB23) -> 0 | AC19: =IFERROR(AB19/$AB$3,"") | AD19: =IFERROR((AB19-Y19)/Y19,"") | AE19: =SUM(AE20:AE23) -> 0 | AF19: =IFERROR(AE19/$AE$3,"") | AG19: =IFERROR((AE19-AB19)/AB19,"") | AH19: =SUM(AH20:AH23) -> 0 | AI19: =IFERROR(AH19/$AH$3,"") | AJ19: =IFERROR((AH19-AE19)/AE19,"") | AK19: =SUM(Tabela373[[#This Row],[JANEIRO]]+Tabela373[[#This Row],[FEVEREIRO]]+Tabela373[[#This Row],[MARÇO]]+Tabela373[[#This Row],[ABRIL]]+Tabela373[[#This Row],[MAIO]]+Tabela373[[#This Row],[JUNHO]]+Tabela373[[#This Row],[JULHO]]+Tabela373[[#This Row],[AGOSTO]]+Tabela373[[#This Row],[SETEMBRO]]+Tabela373[[#This Row],[NOVEMBRO]]+Tabela373[[#This Row],[DEZEMBRO]]) -> 0 | AL19: =IFERROR(AK19/$AK$3,"") | AM19: =AVERAGE(Tabela373[[#This Row],[JANEIRO]],Tabela373[[#This Row],[FEVEREIRO]],Tabela373[[#This Row],[MARÇO]],Tabela373[[#This Row],[ABRIL]],Tabela373[[#This Row],[MAIO]],Tabela373[[#This Row],[JUNHO]],Tabela373[[#This Row],[JULHO]],Tabela373[[#This Row],[AGOSTO]],Tabela373[[#This Row],[SETEMBRO]],Tabela373[[#This Row],[OUTUBRO]],Tabela373[[#This Row],[NOVEMBRO]],Tabela373[[#This Row],[DEZEMBRO]]) -> 0
A20: LOJA FISICA | C20: =IFERROR(B20/$B$3,"") | E20: =IFERROR(D20/$D$3,"") | F20: =IFERROR((D20-B20)/B20,"") | H20: =IFERROR(G20/$G$3,"") | I20: =IFERROR((G20-D20)/D20,"") | K20: =IFERROR(J20/$J$3,"") | L20: =IFERROR((J20-G20)/G20,"") | N20: =IFERROR(M20/$M$3,"") | O20: =IFERROR((M20-J20)/J20,"") | Q20: =IFERROR(P20/$P$3,"") | R20: =IFERROR((P20-M20)/M20,"") | T20: =IFERROR(S20/$S$3,"") | U20: =IFERROR((S20-P20)/P20,"") | W20: =IFERROR(V20/$V$3,"") | X20: =IFERROR((V20-S20)/S20,"") | Z20: =IFERROR(Y20/$Y$3,"") | AA20: =IFERROR((Y20-V20)/V20,"") | AC20: =IFERROR(AB20/$AB$3,"") | AD20: =IFERROR((AB20-Y20)/Y20,"") | AF20: =IFERROR(AE20/$AE$3,"") | AG20: =IFERROR((AE20-AB20)/AB20,"") | AI20: =IFERROR(AH20/$AH$3,"") | AJ20: =IFERROR((AH20-AE20)/AE20,"") | AK20: =SUM(Tabela373[[#This Row],[JANEIRO]]+Tabela373[[#This Row],[FEVEREIRO]]+Tabela373[[#This Row],[MARÇO]]+Tabela373[[#This Row],[ABRIL]]+Tabela373[[#This Row],[MAIO]]+Tabela373[[#This Row],[JUNHO]]+Tabela373[[#This Row],[JULHO]]+Tabela373[[#This Row],[AGOSTO]]+Tabela373[[#This Row],[SETEMBRO]]+Tabela373[[#This Row],[NOVEMBRO]]+Tabela373[[#This Row],[DEZEMBRO]]) -> 0 | AL20: =IFERROR(AK20/$AK$3,"") | AM20: =AVERAGE(Tabela373[[#This Row],[JANEIRO]],Tabela373[[#This Row],[FEVEREIRO]],Tabela373[[#This Row],[MARÇO]],Tabela373[[#This Row],[ABRIL]],Tabela373[[#This Row],[MAIO]],Tabela373[[#This Row],[JUNHO]],Tabela373[[#This Row],[JULHO]],Tabela373[[#This Row],[AGOSTO]],Tabela373[[#This Row],[SETEMBRO]],Tabela373[[#This Row],[OUTUBRO]],Tabela373[[#This Row],[NOVEMBRO]],Tabela373[[#This Row],[DEZEMBRO]]) -> #DIV/0!
A21: MARKETPLACE | C21: =IFERROR(B21/$B$3,"") | E21: =IFERROR(D21/$D$3,"") | F21: =IFERROR((D21-B21)/B21,"") | H21: =IFERROR(G21/$G$3,"") | I21: =IFERROR((G21-D21)/D21,"") | K21: =IFERROR(J21/$J$3,"") | L21: =IFERROR((J21-G21)/G21,"") | N21: =IFERROR(M21/$M$3,"") | O21: =IFERROR((M21-J21)/J21,"") | Q21: =IFERROR(P21/$P$3,"") | R21: =IFERROR((P21-M21)/M21,"") | T21: =IFERROR(S21/$S$3,"") | U21: =IFERROR((S21-P21)/P21,"") | W21: =IFERROR(V21/$V$3,"") | X21: =IFERROR((V21-S21)/S21,"") | Z21: =IFERROR(Y21/$Y$3,"") | AA21: =IFERROR((Y21-V21)/V21,"") | AC21: =IFERROR(AB21/$AB$3,"") | AD21: =IFERROR((AB21-Y21)/Y21,"") | AF21: =IFERROR(AE21/$AE$3,"") | AG21: =IFERROR((AE21-AB21)/AB21,"") | AI21: =IFERROR(AH21/$AH$3,"") | AJ21: =IFERROR((AH21-AE21)/AE21,"") | AK21: =SUM(Tabela373[[#This Row],[JANEIRO]]+Tabela373[[#This Row],[FEVEREIRO]]+Tabela373[[#This Row],[MARÇO]]+Tabela373[[#This Row],[ABRIL]]+Tabela373[[#This Row],[MAIO]]+Tabela373[[#This Row],[JUNHO]]+Tabela373[[#This Row],[JULHO]]+Tabela373[[#This Row],[AGOSTO]]+Tabela373[[#This Row],[SETEMBRO]]+Tabela373[[#This Row],[NOVEMBRO]]+Tabela373[[#This Row],[DEZEMBRO]]) -> 0 | AL21: =IFERROR(AK21/$AK$3,"") | AM21: =AVERAGE(Tabela373[[#This Row],[JANEIRO]],Tabela373[[#This Row],[FEVEREIRO]],Tabela373[[#This Row],[MARÇO]],Tabela373[[#This Row],[ABRIL]],Tabela373[[#This Row],[MAIO]],Tabela373[[#This Row],[JUNHO]],Tabela373[[#This Row],[JULHO]],Tabela373[[#This Row],[AGOSTO]],Tabela373[[#This Row],[SETEMBRO]],Tabela373[[#This Row],[OUTUBRO]],Tabela373[[#This Row],[NOVEMBRO]],Tabela373[[#This Row],[DEZEMBRO]]) -> #DIV/0!
A22: SITE PRÓPRIO | C22: =IFERROR(B22/$B$3,"") | E22: =IFERROR(D22/$D$3,"") | F22: =IFERROR((D22-B22)/B22,"") | H22: =IFERROR(G22/$G$3,"") | I22: =IFERROR((G22-D22)/D22,"") | K22: =IFERROR(J22/$J$3,"") | L22: =IFERROR((J22-G22)/G22,"") | N22: =IFERROR(M22/$M$3,"") | O22: =IFERROR((M22-J22)/J22,"") | Q22: =IFERROR(P22/$P$3,"") | R22: =IFERROR((P22-M22)/M22,"") | T22: =IFERROR(S22/$S$3,"") | U22: =IFERROR((S22-P22)/P22,"") | W22: =IFERROR(V22/$V$3,"") | X22: =IFERROR((V22-S22)/S22,"") | Z22: =IFERROR(Y22/$Y$3,"") | AA22: =IFERROR((Y22-V22)/V22,"") | AC22: =IFERROR(AB22/$AB$3,"") | AD22: =IFERROR((AB22-Y22)/Y22,"") | AF22: =IFERROR(AE22/$AE$3,"") | AG22: =IFERROR((AE22-AB22)/AB22,"") | AI22: =IFERROR(AH22/$AH$3,"") | AJ22: =IFERROR((AH22-AE22)/AE22,"") | AK22: =SUM(Tabela373[[#This Row],[JANEIRO]]+Tabela373[[#This Row],[FEVEREIRO]]+Tabela373[[#This Row],[MARÇO]]+Tabela373[[#This Row],[ABRIL]]+Tabela373[[#This Row],[MAIO]]+Tabela373[[#This Row],[JUNHO]]+Tabela373[[#This Row],[JULHO]]+Tabela373[[#This Row],[AGOSTO]]+Tabela373[[#This Row],[SETEMBRO]]+Tabela373[[#This Row],[NOVEMBRO]]+Tabela373[[#This Row],[DEZEMBRO]]) -> 0 | AL22: =IFERROR(AK22/$AK$3,"") | AM22: =AVERAGE(Tabela373[[#This Row],[JANEIRO]],Tabela373[[#This Row],[FEVEREIRO]],Tabela373[[#This Row],[MARÇO]],Tabela373[[#This Row],[ABRIL]],Tabela373[[#This Row],[MAIO]],Tabela373[[#This Row],[JUNHO]],Tabela373[[#This Row],[JULHO]],Tabela373[[#This Row],[AGOSTO]],Tabela373[[#This Row],[SETEMBRO]],Tabela373[[#This Row],[OUTUBRO]],Tabela373[[#This Row],[NOVEMBRO]],Tabela373[[#This Row],[DEZEMBRO]]) -> #DIV/0!
C23: =IFERROR(B23/$B$3,"") | E23: =IFERROR(D23/$D$3,"") | F23: =IFERROR((D23-B23)/B23,"") | H23: =IFERROR(G23/$G$3,"") | I23: =IFERROR((G23-D23)/D23,"") | K23: =IFERROR(J23/$J$3,"") | L23: =IFERROR((J23-G23)/G23,"") | N23: =IFERROR(M23/$M$3,"") | O23: =IFERROR((M23-J23)/J23,"") | Q23: =IFERROR(P23/$P$3,"") | R23: =IFERROR((P23-M23)/M23,"") | T23: =IFERROR(S23/$S$3,"") | U23: =IFERROR((S23-P23)/P23,"") | W23: =IFERROR(V23/$V$3,"") | X23: =IFERROR((V23-S23)/S23,"") | Z23: =IFERROR(Y23/$Y$3,"") | AA23: =IFERROR((Y23-V23)/V23,"") | AC23: =IFERROR(AB23/$AB$3,"") | AD23: =IFERROR((AB23-Y23)/Y23,"") | AF23: =IFERROR(AE23/$AE$3,"") | AG23: =IFERROR((AE23-AB23)/AB23,"") | AI23: =IFERROR(AH23/$AH$3,"") | AJ23: =IFERROR((AH23-AE23)/AE23,"") | AK23: =SUM(Tabela373[[#This Row],[JANEIRO]]+Tabela373[[#This Row],[FEVEREIRO]]+Tabela373[[#This Row],[MARÇO]]+Tabela373[[#This Row],[ABRIL]]+Tabela373[[#This Row],[MAIO]]+Tabela373[[#This Row],[JUNHO]]+Tabela373[[#This Row],[JULHO]]+Tabela373[[#This Row],[AGOSTO]]+Tabela373[[#This Row],[SETEMBRO]]+Tabela373[[#This Row],[NOVEMBRO]]+Tabela373[[#This Row],[DEZEMBRO]]) -> 0 | AL23: =IFERROR(AK23/$AK$3,"") | AM23: =AVERAGE(Tabela373[[#This Row],[JANEIRO]],Tabela373[[#This Row],[FEVEREIRO]],Tabela373[[#This Row],[MARÇO]],Tabela373[[#This Row],[ABRIL]],Tabela373[[#This Row],[MAIO]],Tabela373[[#This Row],[JUNHO]],Tabela373[[#This Row],[JULHO]],Tabela373[[#This Row],[AGOSTO]],Tabela373[[#This Row],[SETEMBRO]],Tabela373[[#This Row],[OUTUBRO]],Tabela373[[#This Row],[NOVEMBRO]],Tabela373[[#This Row],[DEZEMBRO]]) -> #DIV/0!
A24: FORMA DE VENDA | B24: =SUM(B25:B27) -> 0 | C24: =IFERROR(B24/$B$3,"") | D24: =SUM(D25:D27) -> 0 | E24: =IFERROR(D24/$D$3,"") | F24: =IFERROR((D24-B24)/B24,"") | G24: =SUM(G25:G27) -> 0 | H24: =IFERROR(G24/$G$3,"") | I24: =IFERROR((G24-D24)/D24,"") | J24: =SUM(J25:J27) -> 0 | K24: =IFERROR(J24/$J$3,"") | L24: =IFERROR((J24-G24)/G24,"") | M24: =SUM(M25:M27) -> 0 | N24: =IFERROR(M24/$M$3,"") | O24: =IFERROR((M24-J24)/J24,"") | P24: =SUM(P25:P27) -> 0 | Q24: =IFERROR(P24/$P$3,"") | R24: =IFERROR((P24-M24)/M24,"") | S24: =SUM(S25:S27) -> 0 | T24: =IFERROR(S24/$S$3,"") | U24: =IFERROR((S24-P24)/P24,"") | V24: =SUM(V25:V27) -> 0 | W24: =IFERROR(V24/$V$3,"") | X24: =IFERROR((V24-S24)/S24,"") | Y24: =SUM(Y25:Y27) -> 0 | Z24: =IFERROR(Y24/$Y$3,"") | AA24: =IFERROR((Y24-V24)/V24,"") | AB24: =SUM(AB25:AB27) -> 0 | AC24: =IFERROR(AB24/$AB$3,"") | AD24: =IFERROR((AB24-Y24)/Y24,"") | AE24: =SUM(AE25:AE27) -> 0 | AF24: =IFERROR(AE24/$AE$3,"") | AG24: =IFERROR((AE24-AB24)/AB24,"") | AH24: =SUM(AH25:AH27) -> 0 | AI24: =IFERROR(AH24/$AH$3,"") | AJ24: =IFERROR((AH24-AE24)/AE24,"") | AK24: =SUM(Tabela373[[#This Row],[JANEIRO]]+Tabela373[[#This Row],[FEVEREIRO]]+Tabela373[[#This Row],[MARÇO]]+Tabela373[[#This Row],[ABRIL]]+Tabela373[[#This Row],[MAIO]]+Tabela373[[#This Row],[JUNHO]]+Tabela373[[#This Row],[JULHO]]+Tabela373[[#This Row],[AGOSTO]]+Tabela373[[#This Row],[SETEMBRO]]+Tabela373[[#This Row],[NOVEMBRO]]+Tabela373[[#This Row],[DEZEMBRO]]) -> 0 | AL24: =IFERROR(AK24/$AK$3,"") | AM24: =AVERAGE(Tabela373[[#This Row],[JANEIRO]],Tabela373[[#This Row],[FEVEREIRO]],Tabela373[[#This Row],[MARÇO]],Tabela373[[#This Row],[ABRIL]],Tabela373[[#This Row],[MAIO]],Tabela373[[#This Row],[JUNHO]],Tabela373[[#This Row],[JULHO]],Tabela373[[#This Row],[AGOSTO]],Tabela373[[#This Row],[SETEMBRO]],Tabela373[[#This Row],[OUTUBRO]],Tabela373[[#This Row],[NOVEMBRO]],Tabela373[[#This Row],[DEZEMBRO]]) -> 0
A25: ATACADO | C25: =IFERROR(B25/$B$3,"") | E25: =IFERROR(D25/$D$3,"") | F25: =IFERROR((D25-B25)/B25,"") | H25: =IFERROR(G25/$G$3,"") | I25: =IFERROR((G25-D25)/D25,"") | K25: =IFERROR(J25/$J$3,"") | L25: =IFERROR((J25-G25)/G25,"") | N25: =IFERROR(M25/$M$3,"") | O25: =IFERROR((M25-J25)/J25,"") | Q25: =IFERROR(P25/$P$3,"") | R25: =IFERROR((P25-M25)/M25,"") | T25: =IFERROR(S25/$S$3,"") | U25: =IFERROR((S25-P25)/P25,"") | W25: =IFERROR(V25/$V$3,"") | X25: =IFERROR((V25-S25)/S25,"") | Z25: =IFERROR(Y25/$Y$3,"") | AA25: =IFERROR((Y25-V25)/V25,"") | AC25: =IFERROR(AB25/$AB$3,"") | AD25: =IFERROR((AB25-Y25)/Y25,"") | AF25: =IFERROR(AE25/$AE$3,"") | AG25: =IFERROR((AE25-AB25)/AB25,"") | AI25: =IFERROR(AH25/$AH$3,"") | AJ25: =IFERROR((AH25-AE25)/AE25,"") | AK25: =SUM(Tabela373[[#This Row],[JANEIRO]]+Tabela373[[#This Row],[FEVEREIRO]]+Tabela373[[#This Row],[MARÇO]]+Tabela373[[#This Row],[ABRIL]]+Tabela373[[#This Row],[MAIO]]+Tabela373[[#This Row],[JUNHO]]+Tabela373[[#This Row],[JULHO]]+Tabela373[[#This Row],[AGOSTO]]+Tabela373[[#This Row],[SETEMBRO]]+Tabela373[[#This Row],[NOVEMBRO]]+Tabela373[[#This Row],[DEZEMBRO]]) -> 0 | AL25: =IFERROR(AK25/$AK$3,"") | AM25: =AVERAGE(Tabela373[[#This Row],[JANEIRO]],Tabela373[[#This Row],[FEVEREIRO]],Tabela373[[#This Row],[MARÇO]],Tabela373[[#This Row],[ABRIL]],Tabela373[[#This Row],[MAIO]],Tabela373[[#This Row],[JUNHO]],Tabela373[[#This Row],[JULHO]],Tabela373[[#This Row],[AGOSTO]],Tabela373[[#This Row],[SETEMBRO]],Tabela373[[#This Row],[OUTUBRO]],Tabela373[[#This Row],[NOVEMBRO]],Tabela373[[#This Row],[DEZEMBRO]]) -> #DIV/0!
A26: VAREJO | C26: =IFERROR(B26/$B$3,"") | E26: =IFERROR(D26/$D$3,"") | F26: =IFERROR((D26-B26)/B26,"") | H26: =IFERROR(G26/$G$3,"") | I26: =IFERROR((G26-D26)/D26,"") | K26: =IFERROR(J26/$J$3,"") | L26: =IFERROR((J26-G26)/G26,"") | N26: =IFERROR(M26/$M$3,"") | O26: =IFERROR((M26-J26)/J26,"") | Q26: =IFERROR(P26/$P$3,"") | R26: =IFERROR((P26-M26)/M26,"") | T26: =IFERROR(S26/$S$3,"") | U26: =IFERROR((S26-P26)/P26,"") | W26: =IFERROR(V26/$V$3,"") | X26: =IFERROR((V26-S26)/S26,"") | Z26: =IFERROR(Y26/$Y$3,"") | AA26: =IFERROR((Y26-V26)/V26,"") | AC26: =IFERROR(AB26/$AB$3,"") | AD26: =IFERROR((AB26-Y26)/Y26,"") | AF26: =IFERROR(AE26/$AE$3,"") | AG26: =IFERROR((AE26-AB26)/AB26,"") | AI26: =IFERROR(AH26/$AH$3,"") | AJ26: =IFERROR((AH26-AE26)/AE26,"") | AK26: =SUM(Tabela373[[#This Row],[JANEIRO]]+Tabela373[[#This Row],[FEVEREIRO]]+Tabela373[[#This Row],[MARÇO]]+Tabela373[[#This Row],[ABRIL]]+Tabela373[[#This Row],[MAIO]]+Tabela373[[#This Row],[JUNHO]]+Tabela373[[#This Row],[JULHO]]+Tabela373[[#This Row],[AGOSTO]]+Tabela373[[#This Row],[SETEMBRO]]+Tabela373[[#This Row],[NOVEMBRO]]+Tabela373[[#This Row],[DEZEMBRO]]) -> 0 | AL26: =IFERROR(AK26/$AK$3,"") | AM26: =AVERAGE(Tabela373[[#This Row],[JANEIRO]],Tabela373[[#This Row],[FEVEREIRO]],Tabela373[[#This Row],[MARÇO]],Tabela373[[#This Row],[ABRIL]],Tabela373[[#This Row],[MAIO]],Tabela373[[#This Row],[JUNHO]],Tabela373[[#This Row],[JULHO]],Tabela373[[#This Row],[AGOSTO]],Tabela373[[#This Row],[SETEMBRO]],Tabela373[[#This Row],[OUTUBRO]],Tabela373[[#This Row],[NOVEMBRO]],Tabela373[[#This Row],[DEZEMBRO]]) -> #DIV/0!
C27: =IFERROR(B27/$B$3,"") | E27: =IFERROR(D27/$D$3,"") | F27: =IFERROR((D27-B27)/B27,"") | H27: =IFERROR(G27/$G$3,"") | I27: =IFERROR((G27-D27)/D27,"") | K27: =IFERROR(J27/$J$3,"") | L27: =IFERROR((J27-G27)/G27,"") | N27: =IFERROR(M27/$M$3,"") | O27: =IFERROR((M27-J27)/J27,"") | Q27: =IFERROR(P27/$P$3,"") | R27: =IFERROR((P27-M27)/M27,"") | T27: =IFERROR(S27/$S$3,"") | U27: =IFERROR((S27-P27)/P27,"") | W27: =IFERROR(V27/$V$3,"") | X27: =IFERROR((V27-S27)/S27,"") | Z27: =IFERROR(Y27/$Y$3,"") | AA27: =IFERROR((Y27-V27)/V27,"") | AC27: =IFERROR(AB27/$AB$3,"") | AD27: =IFERROR((AB27-Y27)/Y27,"") | AF27: =IFERROR(AE27/$AE$3,"") | AG27: =IFERROR((AE27-AB27)/AB27,"") | AI27: =IFERROR(AH27/$AH$3,"") | AJ27: =IFERROR((AH27-AE27)/AE27,"") | AK27: =SUM(Tabela373[[#This Row],[JANEIRO]]+Tabela373[[#This Row],[FEVEREIRO]]+Tabela373[[#This Row],[MARÇO]]+Tabela373[[#This Row],[ABRIL]]+Tabela373[[#This Row],[MAIO]]+Tabela373[[#This Row],[JUNHO]]+Tabela373[[#This Row],[JULHO]]+Tabela373[[#This Row],[AGOSTO]]+Tabela373[[#This Row],[SETEMBRO]]+Tabela373[[#This Row],[NOVEMBRO]]+Tabela373[[#This Row],[DEZEMBRO]]) -> 0 | AL27: =IFERROR(AK27/$AK$3,"") | AM27: =AVERAGE(Tabela373[[#This Row],[JANEIRO]],Tabela373[[#This Row],[FEVEREIRO]],Tabela373[[#This Row],[MARÇO]],Tabela373[[#This Row],[ABRIL]],Tabela373[[#This Row],[MAIO]],Tabela373[[#This Row],[JUNHO]],Tabela373[[#This Row],[JULHO]],Tabela373[[#This Row],[AGOSTO]],Tabela373[[#This Row],[SETEMBRO]],Tabela373[[#This Row],[OUTUBRO]],Tabela373[[#This Row],[NOVEMBRO]],Tabela373[[#This Row],[DEZEMBRO]]) -> #DIV/0!
A28: RECEITAS DIVERSAS | B28: =SUM(B29:B30) -> 0 | C28: =IFERROR(B28/$B$3,"") | D28: =SUM(D29:D30) -> 0 | E28: =IFERROR(D28/$D$3,"") | F28: =IFERROR((D28-B28)/B28,"") | G28: =SUM(G29:G30) -> 0 | H28: =IFERROR(G28/$G$3,"") | I28: =IFERROR((G28-D28)/D28,"") | J28: =SUM(J29:J30) -> 0 | K28: =IFERROR(J28/$J$3,"") | L28: =IFERROR((J28-G28)/G28,"") | M28: =SUM(M29:M30) -> 0 | N28: =IFERROR(M28/$M$3,"") | O28: =IFERROR((M28-J28)/J28,"") | P28: =SUM(P29:P30) -> 0 | Q28: =IFERROR(P28/$P$3,"") | R28: =IFERROR((P28-M28)/M28,"") | S28: =SUM(S29:S30) -> 0 | T28: =IFERROR(S28/$S$3,"") | U28: =IFERROR((S28-P28)/P28,"") | V28: =SUM(V29:V30) -> 0 | W28: =IFERROR(V28/$V$3,"") | X28: =IFERROR((V28-S28)/S28,"") | Y28: =SUM(Y29:Y30) -> 0 | Z28: =IFERROR(Y28/$Y$3,"") | AA28: =IFERROR((Y28-V28)/V28,"") | AB28: =SUM(AB29:AB30) -> 0 | AC28: =IFERROR(AB28/$AB$3,"") | AD28: =IFERROR((AB28-Y28)/Y28,"") | AE28: =SUM(AE29:AE30) -> 0 | AF28: =IFERROR(AE28/$AE$3,"") | AG28: =IFERROR((AE28-AB28)/AB28,"") | AH28: =SUM(AH29:AH30) -> 0 | AI28: =IFERROR(AH28/$AH$3,"") | AJ28: =IFERROR((AH28-AE28)/AE28,"") | AK28: =SUM(Tabela373[[#This Row],[JANEIRO]]+Tabela373[[#This Row],[FEVEREIRO]]+Tabela373[[#This Row],[MARÇO]]+Tabela373[[#This Row],[ABRIL]]+Tabela373[[#This Row],[MAIO]]+Tabela373[[#This Row],[JUNHO]]+Tabela373[[#This Row],[JULHO]]+Tabela373[[#This Row],[AGOSTO]]+Tabela373[[#This Row],[SETEMBRO]]+Tabela373[[#This Row],[NOVEMBRO]]+Tabela373[[#This Row],[DEZEMBRO]]) -> 0 | AL28: =IFERROR(AK28/$AK$3,"") | AM28: =AVERAGE(Tabela373[[#This Row],[JANEIRO]],Tabela373[[#This Row],[FEVEREIRO]],Tabela373[[#This Row],[MARÇO]],Tabela373[[#This Row],[ABRIL]],Tabela373[[#This Row],[MAIO]],Tabela373[[#This Row],[JUNHO]],Tabela373[[#This Row],[JULHO]],Tabela373[[#This Row],[AGOSTO]],Tabela373[[#This Row],[SETEMBRO]],Tabela373[[#This Row],[OUTUBRO]],Tabela373[[#This Row],[NOVEMBRO]],Tabela373[[#This Row],[DEZEMBRO]]) -> 0
A29: RECEITAS DE VENDAS DIVERSAS | C29: =IFERROR(B29/$B$3,"") | E29: =IFERROR(D29/$D$3,"") | F29: =IFERROR((D29-B29)/B29,"") | H29: =IFERROR(G29/$G$3,"") | I29: =IFERROR((G29-D29)/D29,"") | K29: =IFERROR(J29/$J$3,"") | L29: =IFERROR((J29-G29)/G29,"") | N29: =IFERROR(M29/$M$3,"") | O29: =IFERROR((M29-J29)/J29,"") | Q29: =IFERROR(P29/$P$3,"") | R29: =IFERROR((P29-M29)/M29,"") | T29: =IFERROR(S29/$S$3,"") | U29: =IFERROR((S29-P29)/P29,"") | W29: =IFERROR(V29/$V$3,"") | X29: =IFERROR((V29-S29)/S29,"") | Z29: =IFERROR(Y29/$Y$3,"") | AA29: =IFERROR((Y29-V29)/V29,"") | AC29: =IFERROR(AB29/$AB$3,"") | AD29: =IFERROR((AB29-Y29)/Y29,"") | AF29: =IFERROR(AE29/$AE$3,"") | AG29: =IFERROR((AE29-AB29)/AB29,"") | AI29: =IFERROR(AH29/$AH$3,"") | AJ29: =IFERROR((AH29-AE29)/AE29,"") | AK29: =SUM(Tabela373[[#This Row],[JANEIRO]]+Tabela373[[#This Row],[FEVEREIRO]]+Tabela373[[#This Row],[MARÇO]]+Tabela373[[#This Row],[ABRIL]]+Tabela373[[#This Row],[MAIO]]+Tabela373[[#This Row],[JUNHO]]+Tabela373[[#This Row],[JULHO]]+Tabela373[[#This Row],[AGOSTO]]+Tabela373[[#This Row],[SETEMBRO]]+Tabela373[[#This Row],[NOVEMBRO]]+Tabela373[[#This Row],[DEZEMBRO]]) -> 0 | AL29: =IFERROR(AK29/$AK$3,"") | AM29: =AVERAGE(Tabela373[[#This Row],[JANEIRO]],Tabela373[[#This Row],[FEVEREIRO]],Tabela373[[#This Row],[MARÇO]],Tabela373[[#This Row],[ABRIL]],Tabela373[[#This Row],[MAIO]],Tabela373[[#This Row],[JUNHO]],Tabela373[[#This Row],[JULHO]],Tabela373[[#This Row],[AGOSTO]],Tabela373[[#This Row],[SETEMBRO]],Tabela373[[#This Row],[OUTUBRO]],Tabela373[[#This Row],[NOVEMBRO]],Tabela373[[#This Row],[DEZEMBRO]]) -> #DIV/0!
C30: =IFERROR(B30/$B$3,"") | E30: =IFERROR(D30/$D$3,"") | F30: =IFERROR((D30-B30)/B30,"") | H30: =IFERROR(G30/$G$3,"") | I30: =IFERROR((G30-D30)/D30,"") | K30: =IFERROR(J30/$J$3,"") | L30: =IFERROR((J30-G30)/G30,"") | N30: =IFERROR(M30/$M$3,"") | O30: =IFERROR((M30-J30)/J30,"") | Q30: =IFERROR(P30/$P$3,"") | R30: =IFERROR((P30-M30)/M30,"") | T30: =IFERROR(S30/$S$3,"") | U30: =IFERROR((S30-P30)/P30,"") | W30: =IFERROR(V30/$V$3,"") | X30: =IFERROR((V30-S30)/S30,"") | Z30: =IFERROR(Y30/$Y$3,"") | AA30: =IFERROR((Y30-V30)/V30,"") | AC30: =IFERROR(AB30/$AB$3,"") | AD30: =IFERROR((AB30-Y30)/Y30,"") | AF30: =IFERROR(AE30/$AE$3,"") | AG30: =IFERROR((AE30-AB30)/AB30,"") | AI30: =IFERROR(AH30/$AH$3,"") | AJ30: =IFERROR((AH30-AE30)/AE30,"") | AK30: =SUM(Tabela373[[#This Row],[JANEIRO]]+Tabela373[[#This Row],[FEVEREIRO]]+Tabela373[[#This Row],[MARÇO]]+Tabela373[[#This Row],[ABRIL]]+Tabela373[[#This Row],[MAIO]]+Tabela373[[#This Row],[JUNHO]]+Tabela373[[#This Row],[JULHO]]+Tabela373[[#This Row],[AGOSTO]]+Tabela373[[#This Row],[SETEMBRO]]+Tabela373[[#This Row],[NOVEMBRO]]+Tabela373[[#This Row],[DEZEMBRO]]) -> 0 | AL30: =IFERROR(AK30/$AK$3,"") | AM30: =AVERAGE(Tabela373[[#This Row],[JANEIRO]],Tabela373[[#This Row],[FEVEREIRO]],Tabela373[[#This Row],[MARÇO]],Tabela373[[#This Row],[ABRIL]],Tabela373[[#This Row],[MAIO]],Tabela373[[#This Row],[JUNHO]],Tabela373[[#This Row],[JULHO]],Tabela373[[#This Row],[AGOSTO]],Tabela373[[#This Row],[SETEMBRO]],Tabela373[[#This Row],[OUTUBRO]],Tabela373[[#This Row],[NOVEMBRO]],Tabela373[[#This Row],[DEZEMBRO]]) -> #DIV/0!
A31: (-) DEDUÇÕES | B31: =B32+B39 -> 0 | C31: =IFERROR(B31/$B$3,"") | D31: =D32+D39 -> 0 | E31: =IFERROR(D31/$D$3,"") | F31: =IFERROR((D31-B31)/B31,"") | G31: =G32+G39 -> 0 | H31: =IFERROR(G31/$G$3,"") | I31: =IFERROR((G31-D31)/D31,"") | J31: =J32+J39 -> 0 | K31: =IFERROR(J31/$J$3,"") | L31: =IFERROR((J31-G31)/G31,"") | M31: =M32+M39 -> 0 | N31: =IFERROR(M31/$M$3,"") | O31: =IFERROR((M31-J31)/J31,"") | P31: =P32+P39 -> 0 | Q31: =IFERROR(P31/$P$3,"") | R31: =IFERROR((P31-M31)/M31,"") | S31: =S32+S39 -> 0 | T31: =IFERROR(S31/$S$3,"") | U31: =IFERROR((S31-P31)/P31,"") | V31: =V32+V39 -> 0 | W31: =IFERROR(V31/$V$3,"") | X31: =IFERROR((V31-S31)/S31,"") | Y31: =Y32+Y39 -> 0 | Z31: =IFERROR(Y31/$Y$3,"") | AA31: =IFERROR((Y31-V31)/V31,"") | AB31: =AB32+AB39 -> 0 | AC31: =IFERROR(AB31/$AB$3,"") | AD31: =IFERROR((AB31-Y31)/Y31,"") | AE31: =AE32+AE39 -> 0 | AF31: =IFERROR(AE31/$AE$3,"") | AG31: =IFERROR((AE31-AB31)/AB31,"") | AH31: =AH32+AH39 -> 0 | AI31: =IFERROR(AH31/$AH$3,"") | AJ31: =IFERROR((AH31-AE31)/AE31,"") | AK31: =SUM(Tabela373[[#This Row],[JANEIRO]]+Tabela373[[#This Row],[FEVEREIRO]]+Tabela373[[#This Row],[MARÇO]]+Tabela373[[#This Row],[ABRIL]]+Tabela373[[#This Row],[MAIO]]+Tabela373[[#This Row],[JUNHO]]+Tabela373[[#This Row],[JULHO]]+Tabela373[[#This Row],[AGOSTO]]+Tabela373[[#This Row],[SETEMBRO]]+Tabela373[[#This Row],[NOVEMBRO]]+Tabela373[[#This Row],[DEZEMBRO]]) -> 0 | AL31: =IFERROR(AK31/$AK$3,"") | AM31: =AVERAGE(Tabela373[[#This Row],[JANEIRO]],Tabela373[[#This Row],[FEVEREIRO]],Tabela373[[#This Row],[MARÇO]],Tabela373[[#This Row],[ABRIL]],Tabela373[[#This Row],[MAIO]],Tabela373[[#This Row],[JUNHO]],Tabela373[[#This Row],[JULHO]],Tabela373[[#This Row],[AGOSTO]],Tabela373[[#This Row],[SETEMBRO]],Tabela373[[#This Row],[OUTUBRO]],Tabela373[[#This Row],[NOVEMBRO]],Tabela373[[#This Row],[DEZEMBRO]]) -> 0
A32: IMPOSTOS S/VENDAS | B32: =SUM(B33:B38) -> 0 | C32: =IFERROR(B32/$B$3,"") | D32: =SUM(D33:D38) -> 0 | E32: =IFERROR(D32/$D$3,"") | F32: =IFERROR((D32-B32)/B32,"") | G32: =SUM(G33:G38) -> 0 | H32: =IFERROR(G32/$G$3,"") | I32: =IFERROR((G32-D32)/D32,"") | J32: =SUM(J33:J38) -> 0 | K32: =IFERROR(J32/$J$3,"") | L32: =IFERROR((J32-G32)/G32,"") | M32: =SUM(M33:M38) -> 0 | N32: =IFERROR(M32/$M$3,"") | O32: =IFERROR((M32-J32)/J32,"") | P32: =SUM(P33:P38) -> 0 | Q32: =IFERROR(P32/$P$3,"") | R32: =IFERROR((P32-M32)/M32,"") | S32: =SUM(S33:S38) -> 0 | T32: =IFERROR(S32/$S$3,"") | U32: =IFERROR((S32-P32)/P32,"") | V32: =SUM(V33:V38) -> 0 | W32: =IFERROR(V32/$V$3,"") | X32: =IFERROR((V32-S32)/S32,"") | Y32: =SUM(Y33:Y38) -> 0 | Z32: =IFERROR(Y32/$Y$3,"") | AA32: =IFERROR((Y32-V32)/V32,"") | AB32: =SUM(AB33:AB38) -> 0 | AC32: =IFERROR(AB32/$AB$3,"") | AD32: =IFERROR((AB32-Y32)/Y32,"") | AE32: =SUM(AE33:AE38) -> 0 | AF32: =IFERROR(AE32/$AE$3,"") | AG32: =IFERROR((AE32-AB32)/AB32,"") | AH32: =SUM(AH33:AH38) -> 0 | AI32: =IFERROR(AH32/$AH$3,"") | AJ32: =IFERROR((AH32-AE32)/AE32,"") | AK32: =SUM(Tabela373[[#This Row],[JANEIRO]]+Tabela373[[#This Row],[FEVEREIRO]]+Tabela373[[#This Row],[MARÇO]]+Tabela373[[#This Row],[ABRIL]]+Tabela373[[#This Row],[MAIO]]+Tabela373[[#This Row],[JUNHO]]+Tabela373[[#This Row],[JULHO]]+Tabela373[[#This Row],[AGOSTO]]+Tabela373[[#This Row],[SETEMBRO]]+Tabela373[[#This Row],[NOVEMBRO]]+Tabela373[[#This Row],[DEZEMBRO]]) -> 0 | AL32: =IFERROR(AK32/$AK$3,"") | AM32: =AVERAGE(Tabela373[[#This Row],[JANEIRO]],Tabela373[[#This Row],[FEVEREIRO]],Tabela373[[#This Row],[MARÇO]],Tabela373[[#This Row],[ABRIL]],Tabela373[[#This Row],[MAIO]],Tabela373[[#This Row],[JUNHO]],Tabela373[[#This Row],[JULHO]],Tabela373[[#This Row],[AGOSTO]],Tabela373[[#This Row],[SETEMBRO]],Tabela373[[#This Row],[OUTUBRO]],Tabela373[[#This Row],[NOVEMBRO]],Tabela373[[#This Row],[DEZEMBRO]]) -> 0
A33: ICMS S/VENDAS | C33: =IFERROR(B33/$B$3,"") | E33: =IFERROR(D33/$D$3,"") | F33: =IFERROR((D33-B33)/B33,"") | H33: =IFERROR(G33/$G$3,"") | I33: =IFERROR((G33-D33)/D33,"") | K33: =IFERROR(J33/$J$3,"") | L33: =IFERROR((J33-G33)/G33,"") | N33: =IFERROR(M33/$M$3,"") | O33: =IFERROR((M33-J33)/J33,"") | Q33: =IFERROR(P33/$P$3,"") | R33: =IFERROR((P33-M33)/M33,"") | T33: =IFERROR(S33/$S$3,"") | U33: =IFERROR((S33-P33)/P33,"") | W33: =IFERROR(V33/$V$3,"") | X33: =IFERROR((V33-S33)/S33,"") | Z33: =IFERROR(Y33/$Y$3,"") | AA33: =IFERROR((Y33-V33)/V33,"") | AC33: =IFERROR(AB33/$AB$3,"") | AD33: =IFERROR((AB33-Y33)/Y33,"") | AF33: =IFERROR(AE33/$AE$3,"") | AG33: =IFERROR((AE33-AB33)/AB33,"") | AI33: =IFERROR(AH33/$AH$3,"") | AJ33: =IFERROR((AH33-AE33)/AE33,"") | AK33: =SUM(Tabela373[[#This Row],[JANEIRO]]+Tabela373[[#This Row],[FEVEREIRO]]+Tabela373[[#This Row],[MARÇO]]+Tabela373[[#This Row],[ABRIL]]+Tabela373[[#This Row],[MAIO]]+Tabela373[[#This Row],[JUNHO]]+Tabela373[[#This Row],[JULHO]]+Tabela373[[#This Row],[AGOSTO]]+Tabela373[[#This Row],[SETEMBRO]]+Tabela373[[#This Row],[NOVEMBRO]]+Tabela373[[#This Row],[DEZEMBRO]]) -> 0 | AL33: =IFERROR(AK33/$AK$3,"") | AM33: =AVERAGE(Tabela373[[#This Row],[JANEIRO]],Tabela373[[#This Row],[FEVEREIRO]],Tabela373[[#This Row],[MARÇO]],Tabela373[[#This Row],[ABRIL]],Tabela373[[#This Row],[MAIO]],Tabela373[[#This Row],[JUNHO]],Tabela373[[#This Row],[JULHO]],Tabela373[[#This Row],[AGOSTO]],Tabela373[[#This Row],[SETEMBRO]],Tabela373[[#This Row],[OUTUBRO]],Tabela373[[#This Row],[NOVEMBRO]],Tabela373[[#This Row],[DEZEMBRO]]) -> #DIV/0!
A34: ISS S/VENDAS | C34: =IFERROR(B34/$B$3,"") | E34: =IFERROR(D34/$D$3,"") | F34: =IFERROR((D34-B34)/B34,"") | H34: =IFERROR(G34/$G$3,"") | I34: =IFERROR((G34-D34)/D34,"") | K34: =IFERROR(J34/$J$3,"") | L34: =IFERROR((J34-G34)/G34,"") | N34: =IFERROR(M34/$M$3,"") | O34: =IFERROR((M34-J34)/J34,"") | Q34: =IFERROR(P34/$P$3,"") | R34: =IFERROR((P34-M34)/M34,"") | T34: =IFERROR(S34/$S$3,"") | U34: =IFERROR((S34-P34)/P34,"") | W34: =IFERROR(V34/$V$3,"") | X34: =IFERROR((V34-S34)/S34,"") | Z34: =IFERROR(Y34/$Y$3,"") | AA34: =IFERROR((Y34-V34)/V34,"") | AC34: =IFERROR(AB34/$AB$3,"") | AD34: =IFERROR((AB34-Y34)/Y34,"") | AF34: =IFERROR(AE34/$AE$3,"") | AG34: =IFERROR((AE34-AB34)/AB34,"") | AI34: =IFERROR(AH34/$AH$3,"") | AJ34: =IFERROR((AH34-AE34)/AE34,"") | AK34: =SUM(Tabela373[[#This Row],[JANEIRO]]+Tabela373[[#This Row],[FEVEREIRO]]+Tabela373[[#This Row],[MARÇO]]+Tabela373[[#This Row],[ABRIL]]+Tabela373[[#This Row],[MAIO]]+Tabela373[[#This Row],[JUNHO]]+Tabela373[[#This Row],[JULHO]]+Tabela373[[#This Row],[AGOSTO]]+Tabela373[[#This Row],[SETEMBRO]]+Tabela373[[#This Row],[NOVEMBRO]]+Tabela373[[#This Row],[DEZEMBRO]]) -> 0 | AL34: =IFERROR(AK34/$AK$3,"") | AM34: =AVERAGE(Tabela373[[#This Row],[JANEIRO]],Tabela373[[#This Row],[FEVEREIRO]],Tabela373[[#This Row],[MARÇO]],Tabela373[[#This Row],[ABRIL]],Tabela373[[#This Row],[MAIO]],Tabela373[[#This Row],[JUNHO]],Tabela373[[#This Row],[JULHO]],Tabela373[[#This Row],[AGOSTO]],Tabela373[[#This Row],[SETEMBRO]],Tabela373[[#This Row],[OUTUBRO]],Tabela373[[#This Row],[NOVEMBRO]],Tabela373[[#This Row],[DEZEMBRO]]) -> #DIV/0!
A35: PIS S/VENDAS | C35: =IFERROR(B35/$B$3,"") | E35: =IFERROR(D35/$D$3,"") | F35: =IFERROR((D35-B35)/B35,"") | H35: =IFERROR(G35/$G$3,"") | I35: =IFERROR((G35-D35)/D35,"") | K35: =IFERROR(J35/$J$3,"") | L35: =IFERROR((J35-G35)/G35,"") | N35: =IFERROR(M35/$M$3,"") | O35: =IFERROR((M35-J35)/J35,"") | Q35: =IFERROR(P35/$P$3,"") | R35: =IFERROR((P35-M35)/M35,"") | T35: =IFERROR(S35/$S$3,"") | U35: =IFERROR((S35-P35)/P35,"") | W35: =IFERROR(V35/$V$3,"") | X35: =IFERROR((V35-S35)/S35,"") | Z35: =IFERROR(Y35/$Y$3,"") | AA35: =IFERROR((Y35-V35)/V35,"") | AC35: =IFERROR(AB35/$AB$3,"") | AD35: =IFERROR((AB35-Y35)/Y35,"") | AF35: =IFERROR(AE35/$AE$3,"") | AG35: =IFERROR((AE35-AB35)/AB35,"") | AI35: =IFERROR(AH35/$AH$3,"") | AJ35: =IFERROR((AH35-AE35)/AE35,"") | AK35: =SUM(Tabela373[[#This Row],[JANEIRO]]+Tabela373[[#This Row],[FEVEREIRO]]+Tabela373[[#This Row],[MARÇO]]+Tabela373[[#This Row],[ABRIL]]+Tabela373[[#This Row],[MAIO]]+Tabela373[[#This Row],[JUNHO]]+Tabela373[[#This Row],[JULHO]]+Tabela373[[#This Row],[AGOSTO]]+Tabela373[[#This Row],[SETEMBRO]]+Tabela373[[#This Row],[NOVEMBRO]]+Tabela373[[#This Row],[DEZEMBRO]]) -> 0 | AL35: =IFERROR(AK35/$AK$3,"") | AM35: =AVERAGE(Tabela373[[#This Row],[JANEIRO]],Tabela373[[#This Row],[FEVEREIRO]],Tabela373[[#This Row],[MARÇO]],Tabela373[[#This Row],[ABRIL]],Tabela373[[#This Row],[MAIO]],Tabela373[[#This Row],[JUNHO]],Tabela373[[#This Row],[JULHO]],Tabela373[[#This Row],[AGOSTO]],Tabela373[[#This Row],[SETEMBRO]],Tabela373[[#This Row],[OUTUBRO]],Tabela373[[#This Row],[NOVEMBRO]],Tabela373[[#This Row],[DEZEMBRO]]) -> #DIV/0!
